Workbook

Sheet サマリー
A1: 2026 冬ゲーム｜コスト状況
A2: 予想コスト・実コスト・残りコストと、マイルストーンまでに必要な作業時間を確認できます。
A4: 予想コスト | D4: 実コスト | G4: 残りコスト | J4: 必要作業時間/日 | M4: 残営業日
A5: =SUM(タスク!G5:G60) -> 327 | D5: =IF(COUNT(タスク!H5:H60)=0,"",SUM(タスク!H5:H60)) -> 56 | G5: =A5-IF(D5="",0,D5) -> 271 | J5: =マイルストーン!H8 -> 4.6724138 | M5: =マイルストーン!D8 -> 58
A7: 最終締切 | B7: 46387
A8: コスト単位 | B8: 1コスト＝作業1時間分
A9: 営業日の扱い | B9: 土日を除外。祝日は除外していません。
A11: 段階 | B11: 締切日 | C11: 残営業日 | D11: 残りコスト | E11: 必要時間/日
A12: プロト | B12: 46326 | C12: =マイルストーン!D4 -> 14 | D12: =マイルストーン!G4 -> 131 | E12: =マイルストーン!H4 -> 9.3571429
A13: アルファ | B13: 46351 | C13: =マイルストーン!D5 -> 32 | D13: =マイルストーン!G5 -> 238 | E13: =マイルストーン!H5 -> 7.4375
A14: ベータ | B14: 46372 | C14: =マイルストーン!D6 -> 47 | D14: =マイルストーン!G6 -> 263 | E14: =マイルストーン!H6 -> 5.5957447
A15: マスター | B15: 46387 | C15: =マイルストーン!D7 -> 58 | D15: =マイルストーン!G7 -> 271 | E15: =マイルストーン!H7 -> 4.6724138
A16: 締め切り | B16: 46387 | C16: =マイルストーン!D8 -> 58 | D16: =マイルストーン!G8 -> 271 | E16: =マイルストーン!H8 -> 4.6724138
A18: 実コストをタスクシートに入力すると、実コスト・残りコスト・必要時間/日が更新されます。

Sheet タスク
A1: タスク一覧
A2: 予想コストは旧表のタスク金額を引継ぎ、実コストは実績入力用です。コスト単位は旧表の定義（1コスト＝作業1時間分）です。
A3: 1コスト：1時間
A4: ID | B4: 段階 | C4: カテゴリ | D4: 作業項目 | E4: 優先度 | F4: 進捗状況 | G4: 予想コスト | H4: 実コスト | I4: コード確認メモ | J4: 補足
A5: T001 | B5: プロト | C5: 当たり判定 | D5: CollisionManagerの管理・接触結果整理 | E5: S | F5: 一部実装 | G5: 5 | I5: CollisionManager.cpp/hあり。判定結果と押し戻しの整理余地
A6: T002 | B6: プロト | C6: 当たり判定 | D6: 球コライダー判定 | E6: S | F6: 完了 | G6: 1 | H6: 1 | I6: SphereCollider.cpp/hあり
A7: T003 | B7: プロト | C7: 当たり判定 | D7: カプセルコライダー判定 | E7: S | F7: 完了 | G7: 2 | H7: 2 | I7: CapsuleCollider.cpp/h、カプセル判定関数あり
A8: T004 | B8: プロト | C8: 当たり判定 | D8: ポリゴンコライダー判定 | E8: S | F8: 完了 | G8: 5 | H8: 5 | I8: PolygonCollider.cpp/hあり。押し戻し・床壁分類との統合確認
A9: T005 | B9: プロト | C9: プレイヤー | D9: 移動 | E9: S | F9: 完了 | G9: 2 | H9: 2 | I9: Playerと移動Stateあり
A10: T006 | B10: プロト | C10: プレイヤー | D10: ジャンプ | E10: S | F10: 完了 | G10: 1 | H10: 1 | I10: PlayerStateJumpあり
A11: T007 | B11: プロト | C11: プレイヤー | D11: ホバー | E11: B | F11: 完了 | G11: 2 | H11: 2 | I11: PlayerStateHoverあり
A12: T008 | B12: プロト | C12: プレイヤー | D12: 回避・ダッシュ | E12: S | F12: 未着手 | G12: 1 | I12: Playerの状態・Physics実装を動作確認
A13: T009 | B13: プロト | C13: プレイヤー | D13: エイム | E13: S | F13: 完了 | G13: 10 | I13: Playerの照準レイ・カメラ参照あり。操作感と座標系確認
A14: T010 | B14: プロト | C14: プレイヤー | D14: 射撃 | E14: S | F14: 進行中 | G14: 9 | I14: PlayerのRayCastと銃モデル描画あり。被弾通知・ダメージ連携を追加
A15: T011 | B15: プロト | C15: プレイヤー | D15: 必殺技 | E15: B | F15: 未着手 | G15: 5 | I15: 元表の項目。仕様未確定
A16: T012 | B16: プロト | C16: カメラ | D16: 通常カメラ | E16: S | F16: 完了 | G16: 7 | H16: 5 | I16: Camera.cpp/hあり
A17: T013 | B17: プロト | C17: カメラ | D17: エイムカメラ | E17: S | F17: 一部実装 | G17: 7 | H17: 5 | I17: 照準時の視点処理をPlayerと統合確認
A18: T014 | B18: プロト | C18: ハッキング | D18: 盤面生成とデータ調整 | E18: S | F18: 進行中 | G18: 7 | I18: HackingManager/Hackableあり。盤面の外部データ化・調整性が残る
A19: T015 | B19: プロト | C19: ハッキング | D19: 盤面移動と経路制約 | E19: S | F19: 進行中 | G19: 5 | I19: Hackableの移動処理あり。全マス条件を検証
A20: T016 | B20: プロト | C20: ハッキング | D20: 成功・失敗の発動 | E20: S | F20: 進行中 | G20: 7 | I20: HackingManager/Hackableあり。敵状態・リセット連携を要確認
A21: T017 | B21: プロト | C21: ハッキング | D21: ハッキング特殊効果 | E21: S | F21: 未着手 | G21: 8 | I21: 黄色マス等。銃強化・伝播・停止などを追加
A22: T018 | B22: プロト | C22: 敵 | D22: 敵ベース | E22: S | F22: 完了 | G22: 4 | H22: 2 | I22: EnemyBase、Hitbox、Hackable、EnemyHPUIあり
A23: T019 | B23: プロト | C23: 敵 | D23: 雑魚敵1（テスト敵） | E23: S | F23: 完了 | G23: 4 | H23: 4 | I23: TestEnemy.cpp/hあり
A24: T020 | B24: アルファ | C24: 敵 | D24: 雑魚敵2（Walker） | E24: S | F24: 進行中 | G24: 6 | I24: WalkerとOrbit/Approach状態、モデルあり。調整・動作確認が残る
A25: T021 | B25: アルファ | C25: 敵 | D25: 雑魚敵3 | E25: A | F25: 未着手 | G25: 4 | I25: 元表の追加敵
A26: T022 | B26: プロト | C26: 敵 | D26: ボス1 | E26: S | F26: 未着手 | G26: 7 | I26: 元表の項目
A27: T023 | B27: アルファ | C27: 敵 | D27: ボス2 | E27: A | F27: 未着手 | G27: 5 | I27: 元表の項目
A28: T024 | B28: アルファ | C28: 敵 | D28: ボス3 | E28: A | F28: 未着手 | G28: 5 | I28: 元表の項目
A29: T025 | B29: プロト | C29: ステージ | D29: ステージ1（仮レイアウト） | E29: S | F29: 一部実装 | G29: 10 | I29: StaticStageあり。プレイ可能区画・導線・配置が必要
A30: T026 | B30: アルファ | C30: ステージ | D30: ステージ2 | E30: A | F30: 未着手 | G30: 10 | I30: 元表の項目
A31: T027 | B31: アルファ | C31: ステージ | D31: ステージ3 | E31: A | F31: 未着手 | G31: 10 | I31: 元表の項目
A32: T028 | B32: プロト | C32: システム | D32: アニメーション基盤・ブレンド | E32: S | F32: 完了 | G32: 15 | H32: 15 | I32: Animator/AnimationLayerあり。遷移と見た目を確認
A33: T029 | B33: プロト | C33: システム | D33: クラス設計・基盤整理 | E33: S | F33: 完了 | G33: 15 | H33: 10 | I33: GameObject/Component/StateMachine等の基盤あり。責務整理
A34: T030 | B34: プロト | C34: 素材 | D34: モデル | E34: S | F34: 進行中 | G34: 5 | I34: Player/Gun/Walkerモデル参照あり。配置・スケール確認
A35: T031 | B35: プロト | C35: 素材 | D35: アニメーション素材 | E35: S | F35: 進行中 | G35: 5 | I35: Animator基盤あり。必要なアニメーション組み込み
A36: T032 | B36: アルファ | C36: 素材 | D36: 画像・テクスチャ | E36: S | F36: 進行中 | G36: 5 | I36: Walker素材/テクスチャあり。ゲーム用調整と反映確認
A37: T033 | B37: ベータ | C37: 素材 | D37: 音素材 | E37: S | F37: 未着手 | G37: 5 | I37: 元表の項目
A38: T034 | B38: アルファ | C38: 演出 | D38: エフェクトマネージャー | E38: S | F38: 未着手 | G38: 2 | I38: 元表の項目
A39: T035 | B39: アルファ | C39: 演出 | D39: エフェクト実装 | E39: S | F39: 未着手 | G39: 4 | I39: 命中・ハッキング・被弾など
A40: T036 | B40: アルファ | C40: 演出 | D40: サウンドマネージャー | E40: S | F40: 未着手 | G40: 2 | I40: 元表の項目
...

Sheet マイルストーン
A1: マイルストーンとカレンダー
A2: 2026年9月〜12月のカレンダー、締切、段階ごとの目標をまとめています。必要作業時間/日は残りコストを残営業日で割った値です。
A3: 段階 | B3: 締切日 | C3: 残り日数 | D3: 残営業日 | E3: 累計予想コスト | F3: 累計実コスト | G3: 残りコスト | H3: 必要作業時間/日 | I3: 到達目標
A4: プロト | B4: 46326 | C4: =MAX(0,B4-TODAY()) -> 19 | D4: =MAX(0,NETWORKDAYS(TODAY()+1,B4)) -> 14 | E4: =SUMIF(タスク!$B$5:$B$60,"プロト",タスク!$G$5:$G$60) -> 187 | F4: =IF(COUNT(タスク!$H$5:$H$60)=0,"",SUMIF(タスク!$B$5:$B$60,"プロト",タスク!$H$5:$H$60)) -> 56 | G4: =E4-IF(F4="",0,F4) -> 131 | H4: =IF(D4=0,"",MAX(0,G4)/D4) -> 9.3571429 | I4: ゲームシーンだけでも遊べるように。プレイヤー、敵一体、ハッキング(黄色マス以外)、ステージ(仮)を実装する
A5: アルファ | B5: 46351 | C5: =MAX(0,B5-TODAY()) -> 44 | D5: =MAX(0,NETWORKDAYS(TODAY()+1,B5)) -> 32 | E5: =SUMIF(タスク!$B$5:$B$60,"プロト",タスク!$G$5:$G$60)+SUMIF(タスク!$B$5:$B$60,"アルファ",タスク!$G$5:$G$60) -> 294 | F5: =IF(COUNT(タスク!$H$5:$H$60)=0,"",SUMIF(タスク!$B$5:$B$60,"プロト",タスク!$H$5:$H$60)+SUMIF(タスク!$B$5:$B$60,"アルファ",タスク!$H$5:$H$60)) -> 56 | G5: =E5-IF(F5="",0,F5) -> 238 | H5: =IF(D5=0,"",MAX(0,G5)/D5) -> 7.4375 | I5: 要素を増やしていく。ゲームシーン以外を実装(見た目は後)、ハッキングの黄色マス追加、敵追加、ステージ追加、改良
A6: ベータ | B6: 46372 | C6: =MAX(0,B6-TODAY()) -> 65 | D6: =MAX(0,NETWORKDAYS(TODAY()+1,B6)) -> 47 | E6: =SUMIF(タスク!$B$5:$B$60,"プロト",タスク!$G$5:$G$60)+SUMIF(タスク!$B$5:$B$60,"アルファ",タスク!$G$5:$G$60)+SUMIF(タスク!$B$5:$B$60,"ベータ",タスク!$G$5:$G$60) -> 319 | F6: =IF(COUNT(タスク!$H$5:$H$60)=0,"",SUMIF(タスク!$B$5:$B$60,"プロト",タスク!$H$5:$H$60)+SUMIF(タスク!$B$5:$B$60,"アルファ",タスク!$H$5:$H$60)+SUMIF(タスク!$B$5:$B$60,"ベータ",タスク!$H$5:$H$60)) -> 56 | G6: =E6-IF(F6="",0,F6) -> 263 | H6: =IF(D6=0,"",MAX(0,G6)/D6) -> 5.5957447 | I6: 見た目を良くしていく。同時にレベルデザインやその他の改良なども行う。
A7: マスター | B7: 46387 | C7: =MAX(0,B7-TODAY()) -> 80 | D7: =MAX(0,NETWORKDAYS(TODAY()+1,B7)) -> 58 | E7: =SUMIF(タスク!$B$5:$B$60,"プロト",タスク!$G$5:$G$60)+SUMIF(タスク!$B$5:$B$60,"アルファ",タスク!$G$5:$G$60)+SUMIF(タスク!$B$5:$B$60,"ベータ",タスク!$G$5:$G$60)+SUMIF(タスク!$B$5:$B$60,"マスター",タスク!$G$5:$G$60) -> 327 | F7: =IF(COUNT(タスク!$H$5:$H$60)=0,"",SUMIF(タスク!$B$5:$B$60,"プロト",タスク!$H$5:$H$60)+SUMIF(タスク!$B$5:$B$60,"アルファ",タスク!$H$5:$H$60)+SUMIF(タスク!$B$5:$B$60,"ベータ",タスク!$H$5:$H$60)+SUMIF(タスク!$B$5:$B$60,"マスター",タスク!$H$5:$H$60)) -> 56 | G7: =E7-IF(F7="",0,F7) -> 271 | H7: =IF(D7=0,"",MAX(0,G7)/D7) -> 4.6724138 | I7: 細かいところを調整。見た目とか難易度とか
A8: 締め切り | B8: 46387 | C8: =MAX(0,B8-TODAY()) -> 80 | D8: =MAX(0,NETWORKDAYS(TODAY()+1,B8)) -> 58 | E8: =SUMIF(タスク!$B$5:$B$60,"プロト",タスク!$G$5:$G$60)+SUMIF(タスク!$B$5:$B$60,"アルファ",タスク!$G$5:$G$60)+SUMIF(タスク!$B$5:$B$60,"ベータ",タスク!$G$5:$G$60)+SUMIF(タスク!$B$5:$B$60,"マスター",タスク!$G$5:$G$60) -> 327 | F8: =IF(COUNT(タスク!$H$5:$H$60)=0,"",SUMIF(タスク!$B$5:$B$60,"プロト",タスク!$H$5:$H$60)+SUMIF(タスク!$B$5:$B$60,"アルファ",タスク!$H$5:$H$60)+SUMIF(タスク!$B$5:$B$60,"ベータ",タスク!$H$5:$H$60)+SUMIF(タスク!$B$5:$B$60,"マスター",タスク!$H$5:$H$60)) -> 56 | G8: =E8-IF(F8="",0,F8) -> 271 | H8: =IF(D8=0,"",MAX(0,G8)/D8) -> 4.6724138 | I8: 締め切り
K12: 10月 2026年
K13: 日 | L13: 月 | M13: 火 | N13: 水 | O13: 木 | P13: 金 | Q13: 土
O14: 1 | P14: 2 | Q14: 3
K15: 4 | L15: 5 | M15: 6 | N15: 7 | O15: 8 | P15: 9 | Q15: 10
K16: 11 | L16: 12 | M16: 13 | N16: 14 | O16: 15 | P16: 16 | Q16: 17
K17: 18 | L17: 19 | M17: 20 | N17: 21 | O17: 22 | P17: 23 | Q17: 24
K18: 25 | L18: 26 | M18: 27 | N18: 28 | O18: 29 | P18: 30 | Q18: 31
K20: 11月 2026年
K21: 日 | L21: 月 | M21: 火 | N21: 水 | O21: 木 | P21: 金 | Q21: 土
K22: 1 | L22: 2 | M22: 3 | N22: 4 | O22: 5 | P22: 6 | Q22: 7
K23: 8 | L23: 9 | M23: 10 | N23: 11 | O23: 12 | P23: 13 | Q23: 14
K24: 15 | L24: 16 | M24: 17 | N24: 18 | O24: 19 | P24: 20 | Q24: 21
K25: 22 | L25: 23 | M25: 24 | N25: 25 | O25: 26 | P25: 27 | Q25: 28
K26: 29 | L26: 30
K28: 12月 2026年
K29: 日 | L29: 月 | M29: 火 | N29: 水 | O29: 木 | P29: 金 | Q29: 土
M30: 1 | N30: 2 | O30: 3 | P30: 4 | Q30: 5
K31: 6 | L31: 7 | M31: 8 | N31: 9 | O31: 10 | P31: 11 | Q31: 12
K32: 13 | L32: 14 | M32: 15 | N32: 16 | O32: 17 | P32: 18 | Q32: 19
K33: 20 | L33: 21 | M33: 22 | N33: 23 | O33: 24 | P33: 25 | Q33: 26
K34: 27 | L34: 28 | M34: 29 | N34: 30 | O34: 31
