Workbook

Sheet サマリー
A1: 2026 冬ゲーム｜コスト状況
A2: 予想コスト・実コスト・残りコストと、マイルストーンまでに必要な作業時間を確認できます。
A4: 予想コスト | D4: 実コスト | G4: 残りコスト | J4: 必要作業時間/日 | M4: 残営業日
A5: =SUM(タスク!G5:G300) -> 317 | D5: =IF(COUNT(タスク!H5:H300)=0,"",SUM(タスク!H5:H300)) -> 56 | G5: =A5-IF(D5="",0,D5) -> 261 | J5: =マイルストーン!H8 -> 4.5 | M5: =マイルストーン!D8 -> 58
A7: 最終締切 | B7: 46387
A8: コスト単位 | B8: 1コスト＝作業1時間分
A9: 営業日の扱い | B9: 土日を除外。祝日は除外していません。
A11: 段階 | B11: 締切日 | C11: 残営業日 | D11: 残りコスト | E11: 必要時間/日
A12: プロト | B12: 46326 | C12: =マイルストーン!D4 -> 14 | D12: =マイルストーン!G4 -> 121 | E12: =マイルストーン!H4 -> 8.6428571
A13: アルファ | B13: 46351 | C13: =マイルストーン!D5 -> 32 | D13: =マイルストーン!G5 -> 228 | E13: =マイルストーン!H5 -> 7.125
A14: ベータ | B14: 46372 | C14: =マイルストーン!D6 -> 47 | D14: =マイルストーン!G6 -> 253 | E14: =マイルストーン!H6 -> 5.3829787
A15: マスター | B15: 46387 | C15: =マイルストーン!D7 -> 58 | D15: =マイルストーン!G7 -> 261 | E15: =マイルストーン!H7 -> 4.5
A16: 締め切り | B16: 46387 | C16: =マイルストーン!D8 -> 58 | D16: =マイルストーン!G8 -> 261 | E16: =マイルストーン!H8 -> 4.5
A18: 実コストをタスクシートに入力すると、実コスト・残りコスト・必要時間/日が更新されます。

Sheet タスク
A1: タスク入力・管理
A2: 新しいタスクは表の次の空行に追加してください。K列を「非表示」にすると、その項目を一覧から隠せます。
A3: 1コスト：1時間
A4: ID | B4: 段階 | C4: カテゴリ | D4: 作業項目 | E4: 優先度 | F4: 進捗状況 | G4: 予想コスト | H4: 実コスト | I4: コード確認メモ | J4: 補足 | K4: 表示 | AA4: 段階順 | AB4: 一覧順キー
A5: T001 | B5: プロト | C5: 当たり判定 | D5: CollisionManagerの管理・接触結果整理 | E5: S | F5: 一部実装 | G5: 5 | I5: CollisionManager.cpp/hあり。判定結果と押し戻しの整理余地 | K5: 表示 | AA5: =IF(B5="プロト",1,IF(B5="アルファ",2,IF(B5="ベータ",3,IF(B5="マスター",4,5)))) -> 1 | AB5: =IF(AND(A5<>"",K5<>"非表示",IF(タスク一覧!$B$4="すべて",TRUE,B5=タスク一覧!$B$4),IF(タスク一覧!$E$4="すべて",TRUE,C5=タスク一覧!$E$4),IF(タスク一覧!$H$4="すべて",TRUE,IF(タスク一覧!$H$4="完了以外",F5<>"完了",F5=タスク一覧!$H$4))),AA5*1000000+COUNTIF($C$5:$C$300,"<"&C5)*1000+ROW(),1000000000000) -> 1050005
A6: T002 | B6: プロト | C6: 当たり判定 | D6: 球コライダー判定 | E6: S | F6: 完了 | G6: 1 | H6: 1 | I6: SphereCollider.cpp/hあり | K6: 表示 | AA6: =IF(B6="プロト",1,IF(B6="アルファ",2,IF(B6="ベータ",3,IF(B6="マスター",4,5)))) -> 1 | AB6: =IF(AND(A6<>"",K6<>"非表示",IF(タスク一覧!$B$4="すべて",TRUE,B6=タスク一覧!$B$4),IF(タスク一覧!$E$4="すべて",TRUE,C6=タスク一覧!$E$4),IF(タスク一覧!$H$4="すべて",TRUE,IF(タスク一覧!$H$4="完了以外",F6<>"完了",F6=タスク一覧!$H$4))),AA6*1000000+COUNTIF($C$5:$C$300,"<"&C6)*1000+ROW(),1000000000000) -> 1050006
A7: T003 | B7: プロト | C7: 当たり判定 | D7: カプセルコライダー判定 | E7: S | F7: 完了 | G7: 2 | H7: 2 | I7: CapsuleCollider.cpp/h、カプセル判定関数あり | K7: 表示 | AA7: =IF(B7="プロト",1,IF(B7="アルファ",2,IF(B7="ベータ",3,IF(B7="マスター",4,5)))) -> 1 | AB7: =IF(AND(A7<>"",K7<>"非表示",IF(タスク一覧!$B$4="すべて",TRUE,B7=タスク一覧!$B$4),IF(タスク一覧!$E$4="すべて",TRUE,C7=タスク一覧!$E$4),IF(タスク一覧!$H$4="すべて",TRUE,IF(タスク一覧!$H$4="完了以外",F7<>"完了",F7=タスク一覧!$H$4))),AA7*1000000+COUNTIF($C$5:$C$300,"<"&C7)*1000+ROW(),1000000000000) -> 1050007
A8: T004 | B8: プロト | C8: 当たり判定 | D8: ポリゴンコライダー判定 | E8: S | F8: 完了 | G8: 5 | H8: 5 | I8: PolygonCollider.cpp/hあり。押し戻し・床壁分類との統合確認 | K8: 表示 | AA8: =IF(B8="プロト",1,IF(B8="アルファ",2,IF(B8="ベータ",3,IF(B8="マスター",4,5)))) -> 1 | AB8: =IF(AND(A8<>"",K8<>"非表示",IF(タスク一覧!$B$4="すべて",TRUE,B8=タスク一覧!$B$4),IF(タスク一覧!$E$4="すべて",TRUE,C8=タスク一覧!$E$4),IF(タスク一覧!$H$4="すべて",TRUE,IF(タスク一覧!$H$4="完了以外",F8<>"完了",F8=タスク一覧!$H$4))),AA8*1000000+COUNTIF($C$5:$C$300,"<"&C8)*1000+ROW(),1000000000000) -> 1050008
A9: T005 | B9: プロト | C9: プレイヤー | D9: 移動 | E9: S | F9: 完了 | G9: 2 | H9: 2 | I9: Playerと移動Stateあり | K9: 表示 | AA9: =IF(B9="プロト",1,IF(B9="アルファ",2,IF(B9="ベータ",3,IF(B9="マスター",4,5)))) -> 1 | AB9: =IF(AND(A9<>"",K9<>"非表示",IF(タスク一覧!$B$4="すべて",TRUE,B9=タスク一覧!$B$4),IF(タスク一覧!$E$4="すべて",TRUE,C9=タスク一覧!$E$4),IF(タスク一覧!$H$4="すべて",TRUE,IF(タスク一覧!$H$4="完了以外",F9<>"完了",F9=タスク一覧!$H$4))),AA9*1000000+COUNTIF($C$5:$C$300,"<"&C9)*1000+ROW(),1000000000000) -> 1023009
A10: T006 | B10: プロト | C10: プレイヤー | D10: ジャンプ | E10: S | F10: 完了 | G10: 1 | H10: 1 | I10: PlayerStateJumpあり | K10: 表示 | AA10: =IF(B10="プロト",1,IF(B10="アルファ",2,IF(B10="ベータ",3,IF(B10="マスター",4,5)))) -> 1 | AB10: =IF(AND(A10<>"",K10<>"非表示",IF(タスク一覧!$B$4="すべて",TRUE,B10=タスク一覧!$B$4),IF(タスク一覧!$E$4="すべて",TRUE,C10=タスク一覧!$E$4),IF(タスク一覧!$H$4="すべて",TRUE,IF(タスク一覧!$H$4="完了以外",F10<>"完了",F10=タスク一覧!$H$4))),AA10*1000000+COUNTIF($C$5:$C$300,"<"&C10)*1000+ROW(),1000000000000) -> 1023010
A11: T007 | B11: プロト | C11: プレイヤー | D11: ホバー | E11: B | F11: 完了 | G11: 2 | H11: 2 | I11: PlayerStateHoverあり | K11: 表示 | AA11: =IF(B11="プロト",1,IF(B11="アルファ",2,IF(B11="ベータ",3,IF(B11="マスター",4,5)))) -> 1 | AB11: =IF(AND(A11<>"",K11<>"非表示",IF(タスク一覧!$B$4="すべて",TRUE,B11=タスク一覧!$B$4),IF(タスク一覧!$E$4="すべて",TRUE,C11=タスク一覧!$E$4),IF(タスク一覧!$H$4="すべて",TRUE,IF(タスク一覧!$H$4="完了以外",F11<>"完了",F11=タスク一覧!$H$4))),AA11*1000000+COUNTIF($C$5:$C$300,"<"&C11)*1000+ROW(),1000000000000) -> 1023011
A12: T008 | B12: プロト | C12: プレイヤー | D12: 回避・ダッシュ | E12: S | F12: 未着手 | G12: 1 | I12: Playerの状態・Physics実装を動作確認 | K12: 表示 | AA12: =IF(B12="プロト",1,IF(B12="アルファ",2,IF(B12="ベータ",3,IF(B12="マスター",4,5)))) -> 1 | AB12: =IF(AND(A12<>"",K12<>"非表示",IF(タスク一覧!$B$4="すべて",TRUE,B12=タスク一覧!$B$4),IF(タスク一覧!$E$4="すべて",TRUE,C12=タスク一覧!$E$4),IF(タスク一覧!$H$4="すべて",TRUE,IF(タスク一覧!$H$4="完了以外",F12<>"完了",F12=タスク一覧!$H$4))),AA12*1000000+COUNTIF($C$5:$C$300,"<"&C12)*1000+ROW(),1000000000000) -> 1023012
A13: T009 | B13: プロト | C13: プレイヤー | D13: エイム | E13: S | F13: 完了 | G13: 10 | I13: Playerの照準レイ・カメラ参照あり。操作感と座標系確認 | K13: 表示 | AA13: =IF(B13="プロト",1,IF(B13="アルファ",2,IF(B13="ベータ",3,IF(B13="マスター",4,5)))) -> 1 | AB13: =IF(AND(A13<>"",K13<>"非表示",IF(タスク一覧!$B$4="すべて",TRUE,B13=タスク一覧!$B$4),IF(タスク一覧!$E$4="すべて",TRUE,C13=タスク一覧!$E$4),IF(タスク一覧!$H$4="すべて",TRUE,IF(タスク一覧!$H$4="完了以外",F13<>"完了",F13=タスク一覧!$H$4))),AA13*1000000+COUNTIF($C$5:$C$300,"<"&C13)*1000+ROW(),1000000000000) -> 1023013
A14: T010 | B14: プロト | C14: プレイヤー | D14: 射撃 | E14: S | F14: 進行中 | G14: 9 | I14: PlayerのRayCastと銃モデル描画あり。被弾通知・ダメージ連携を追加 | K14: 表示 | AA14: =IF(B14="プロト",1,IF(B14="アルファ",2,IF(B14="ベータ",3,IF(B14="マスター",4,5)))) -> 1 | AB14: =IF(AND(A14<>"",K14<>"非表示",IF(タスク一覧!$B$4="すべて",TRUE,B14=タスク一覧!$B$4),IF(タスク一覧!$E$4="すべて",TRUE,C14=タスク一覧!$E$4),IF(タスク一覧!$H$4="すべて",TRUE,IF(タスク一覧!$H$4="完了以外",F14<>"完了",F14=タスク一覧!$H$4))),AA14*1000000+COUNTIF($C$5:$C$300,"<"&C14)*1000+ROW(),1000000000000) -> 1023014
A15: T011 | B15: プロト | C15: プレイヤー | D15: 必殺技 | E15: B | F15: 未着手 | G15: 5 | I15: 元表の項目。仕様未確定 | K15: 表示 | AA15: =IF(B15="プロト",1,IF(B15="アルファ",2,IF(B15="ベータ",3,IF(B15="マスター",4,5)))) -> 1 | AB15: =IF(AND(A15<>"",K15<>"非表示",IF(タスク一覧!$B$4="すべて",TRUE,B15=タスク一覧!$B$4),IF(タスク一覧!$E$4="すべて",TRUE,C15=タスク一覧!$E$4),IF(タスク一覧!$H$4="すべて",TRUE,IF(タスク一覧!$H$4="完了以外",F15<>"完了",F15=タスク一覧!$H$4))),AA15*1000000+COUNTIF($C$5:$C$300,"<"&C15)*1000+ROW(),1000000000000) -> 1023015
A16: T012 | B16: プロト | C16: カメラ | D16: 通常カメラ | E16: S | F16: 完了 | G16: 7 | H16: 5 | I16: Camera.cpp/hあり | K16: 表示 | AA16: =IF(B16="プロト",1,IF(B16="アルファ",2,IF(B16="ベータ",3,IF(B16="マスター",4,5)))) -> 1 | AB16: =IF(AND(A16<>"",K16<>"非表示",IF(タスク一覧!$B$4="すべて",TRUE,B16=タスク一覧!$B$4),IF(タスク一覧!$E$4="すべて",TRUE,C16=タスク一覧!$E$4),IF(タスク一覧!$H$4="すべて",TRUE,IF(タスク一覧!$H$4="完了以外",F16<>"完了",F16=タスク一覧!$H$4))),AA16*1000000+COUNTIF($C$5:$C$300,"<"&C16)*1000+ROW(),1000000000000) -> 1001016
A17: T013 | B17: プロト | C17: カメラ | D17: エイムカメラ | E17: S | F17: 一部実装 | G17: 7 | H17: 5 | I17: 照準時の視点処理をPlayerと統合確認 | K17: 表示 | AA17: =IF(B17="プロト",1,IF(B17="アルファ",2,IF(B17="ベータ",3,IF(B17="マスター",4,5)))) -> 1 | AB17: =IF(AND(A17<>"",K17<>"非表示",IF(タスク一覧!$B$4="すべて",TRUE,B17=タスク一覧!$B$4),IF(タスク一覧!$E$4="すべて",TRUE,C17=タスク一覧!$E$4),IF(タスク一覧!$H$4="すべて",TRUE,IF(タスク一覧!$H$4="完了以外",F17<>"完了",F17=タスク一覧!$H$4))),AA17*1000000+COUNTIF($C$5:$C$300,"<"&C17)*1000+ROW(),1000000000000) -> 1001017
A18: T014 | B18: プロト | C18: ハッキング | D18: 盤面生成とデータ調整 | E18: S | F18: 一部実装 | G18: 7 | I18: HackingManager/Hackableあり。盤面の外部データ化・調整性が残る | K18: 表示 | AA18: =IF(B18="プロト",1,IF(B18="アルファ",2,IF(B18="ベータ",3,IF(B18="マスター",4,5)))) -> 1 | AB18: =IF(AND(A18<>"",K18<>"非表示",IF(タスク一覧!$B$4="すべて",TRUE,B18=タスク一覧!$B$4),IF(タスク一覧!$E$4="すべて",TRUE,C18=タスク一覧!$E$4),IF(タスク一覧!$H$4="すべて",TRUE,IF(タスク一覧!$H$4="完了以外",F18<>"完了",F18=タスク一覧!$H$4))),AA18*1000000+COUNTIF($C$5:$C$300,"<"&C18)*1000+ROW(),1000000000000) -> 1018018
A19: T015 | B19: プロト | C19: ハッキング | D19: 盤面移動と経路制約 | E19: S | F19: コードあり・要確認 | G19: 5 | I19: Hackableの移動処理あり。全マス条件を検証 | K19: 表示 | AA19: =IF(B19="プロト",1,IF(B19="アルファ",2,IF(B19="ベータ",3,IF(B19="マスター",4,5)))) -> 1 | AB19: =IF(AND(A19<>"",K19<>"非表示",IF(タスク一覧!$B$4="すべて",TRUE,B19=タスク一覧!$B$4),IF(タスク一覧!$E$4="すべて",TRUE,C19=タスク一覧!$E$4),IF(タスク一覧!$H$4="すべて",TRUE,IF(タスク一覧!$H$4="完了以外",F19<>"完了",F19=タスク一覧!$H$4))),AA19*1000000+COUNTIF($C$5:$C$300,"<"&C19)*1000+ROW(),1000000000000) -> 1018019
A20: T016 | B20: プロト | C20: ハッキング | D20: 成功・失敗の発動 | E20: S | F20: 一部実装 | G20: 7 | I20: HackingManager/Hackableあり。敵状態・リセット連携を要確認 | K20: 表示 | AA20: =IF(B20="プロト",1,IF(B20="アルファ",2,IF(B20="ベータ",3,IF(B20="マスター",4,5)))) -> 1 | AB20: =IF(AND(A20<>"",K20<>"非表示",IF(タスク一覧!$B$4="すべて",TRUE,B20=タスク一覧!$B$4),IF(タスク一覧!$E$4="すべて",TRUE,C20=タスク一覧!$E$4),IF(タスク一覧!$H$4="すべて",TRUE,IF(タスク一覧!$H$4="完了以外",F20<>"完了",F20=タスク一覧!$H$4))),AA20*1000000+COUNTIF($C$5:$C$300,"<"&C20)*1000+ROW(),1000000000000) -> 1018020
A21: T017 | B21: プロト | C21: ハッキング | D21: ハッキング特殊効果 | E21: S | F21: 一部実装 | G21: 8 | I21: 黄色マス等。銃強化・伝播・停止などを追加 | K21: 表示 | AA21: =IF(B21="プロト",1,IF(B21="アルファ",2,IF(B21="ベータ",3,IF(B21="マスター",4,5)))) -> 1 | AB21: =IF(AND(A21<>"",K21<>"非表示",IF(タスク一覧!$B$4="すべて",TRUE,B21=タスク一覧!$B$4),IF(タスク一覧!$E$4="すべて",TRUE,C21=タスク一覧!$E$4),IF(タスク一覧!$H$4="すべて",TRUE,IF(タスク一覧!$H$4="完了以外",F21<>"完了",F21=タスク一覧!$H$4))),AA21*1000000+COUNTIF($C$5:$C$300,"<"&C21)*1000+ROW(),1000000000000) -> 1018021
A22: T018 | B22: プロト | C22: 敵 | D22: 敵ベース | E22: S | F22: コードあり・要確認 | G22: 4 | H22: 2 | I22: EnemyBase、Hitbox、Hackable、EnemyHPUIあり | K22: 表示 | AA22: =IF(B22="プロト",1,IF(B22="アルファ",2,IF(B22="ベータ",3,IF(B22="マスター",4,5)))) -> 1 | AB22: =IF(AND(A22<>"",K22<>"非表示",IF(タスク一覧!$B$4="すべて",TRUE,B22=タスク一覧!$B$4),IF(タスク一覧!$E$4="すべて",TRUE,C22=タスク一覧!$E$4),IF(タスク一覧!$H$4="すべて",TRUE,IF(タスク一覧!$H$4="完了以外",F22<>"完了",F22=タスク一覧!$H$4))),AA22*1000000+COUNTIF($C$5:$C$300,"<"&C22)*1000+ROW(),1000000000000) -> 1041022
A23: T019 | B23: プロト | C23: 敵 | D23: 雑魚敵1（テスト敵） | E23: S | F23: コードあり・要確認 | G23: 4 | H23: 4 | I23: TestEnemy.cpp/hあり | K23: 表示 | AA23: =IF(B23="プロト",1,IF(B23="アルファ",2,IF(B23="ベータ",3,IF(B23="マスター",4,5)))) -> 1 | AB23: =IF(AND(A23<>"",K23<>"非表示",IF(タスク一覧!$B$4="すべて",TRUE,B23=タスク一覧!$B$4),IF(タスク一覧!$E$4="すべて",TRUE,C23=タスク一覧!$E$4),IF(タスク一覧!$H$4="すべて",TRUE,IF(タスク一覧!$H$4="完了以外",F23<>"完了",F23=タスク一覧!$H$4))),AA23*1000000+COUNTIF($C$5:$C$300,"<"&C23)*1000+ROW(),1000000000000) -> 1041023
A24: T020 | B24: アルファ | C24: 敵 | D24: 雑魚敵2（Walker） | E24: S | F24: 一部実装 | G24: 6 | I24: WalkerとOrbit/Approach状態、モデルあり。調整・動作確認が残る | K24: 表示 | AA24: =IF(B24="プロト",1,IF(B24="アルファ",2,IF(B24="ベータ",3,IF(B24="マスター",4,5)))) -> 2 | AB24: =IF(AND(A24<>"",K24<>"非表示",IF(タスク一覧!$B$4="すべて",TRUE,B24=タスク一覧!$B$4),IF(タスク一覧!$E$4="すべて",TRUE,C24=タスク一覧!$E$4),IF(タスク一覧!$H$4="すべて",TRUE,IF(タスク一覧!$H$4="完了以外",F24<>"完了",F24=タスク一覧!$H$4))),AA24*1000000+COUNTIF($C$5:$C$300,"<"&C24)*1000+ROW(),1000000000000) -> 2041024
A25: T021 | B25: アルファ | C25: 敵 | D25: 雑魚敵3 | E25: A | F25: 未着手 | G25: 4 | I25: 元表の追加敵 | K25: 表示 | AA25: =IF(B25="プロト",1,IF(B25="アルファ",2,IF(B25="ベータ",3,IF(B25="マスター",4,5)))) -> 2 | AB25: =IF(AND(A25<>"",K25<>"非表示",IF(タスク一覧!$B$4="すべて",TRUE,B25=タスク一覧!$B$4),IF(タスク一覧!$E$4="すべて",TRUE,C25=タスク一覧!$E$4),IF(タスク一覧!$H$4="すべて",TRUE,IF(タスク一覧!$H$4="完了以外",F25<>"完了",F25=タスク一覧!$H$4))),AA25*1000000+COUNTIF($C$5:$C$300,"<"&C25)*1000+ROW(),1000000000000) -> 2041025
A26: T022 | B26: プロト | C26: 敵 | D26: ボス1 | E26: S | F26: 未着手 | G26: 7 | I26: 元表の項目 | K26: 表示 | AA26: =IF(B26="プロト",1,IF(B26="アルファ",2,IF(B26="ベータ",3,IF(B26="マスター",4,5)))) -> 1 | AB26: =IF(AND(A26<>"",K26<>"非表示",IF(タスク一覧!$B$4="すべて",TRUE,B26=タスク一覧!$B$4),IF(タスク一覧!$E$4="すべて",TRUE,C26=タスク一覧!$E$4),IF(タスク一覧!$H$4="すべて",TRUE,IF(タスク一覧!$H$4="完了以外",F26<>"完了",F26=タスク一覧!$H$4))),AA26*1000000+COUNTIF($C$5:$C$300,"<"&C26)*1000+ROW(),1000000000000) -> 1041026
A27: T023 | B27: アルファ | C27: 敵 | D27: ボス2 | E27: A | F27: 未着手 | G27: 5 | I27: 元表の項目 | K27: 表示 | AA27: =IF(B27="プロト",1,IF(B27="アルファ",2,IF(B27="ベータ",3,IF(B27="マスター",4,5)))) -> 2 | AB27: =IF(AND(A27<>"",K27<>"非表示",IF(タスク一覧!$B$4="すべて",TRUE,B27=タスク一覧!$B$4),IF(タスク一覧!$E$4="すべて",TRUE,C27=タスク一覧!$E$4),IF(タスク一覧!$H$4="すべて",TRUE,IF(タスク一覧!$H$4="完了以外",F27<>"完了",F27=タスク一覧!$H$4))),AA27*1000000+COUNTIF($C$5:$C$300,"<"&C27)*1000+ROW(),1000000000000) -> 2041027
A28: T024 | B28: アルファ | C28: 敵 | D28: ボス3 | E28: A | F28: 未着手 | G28: 5 | I28: 元表の項目 | K28: 表示 | AA28: =IF(B28="プロト",1,IF(B28="アルファ",2,IF(B28="ベータ",3,IF(B28="マスター",4,5)))) -> 2 | AB28: =IF(AND(A28<>"",K28<>"非表示",IF(タスク一覧!$B$4="すべて",TRUE,B28=タスク一覧!$B$4),IF(タスク一覧!$E$4="すべて",TRUE,C28=タスク一覧!$E$4),IF(タスク一覧!$H$4="すべて",TRUE,IF(タスク一覧!$H$4="完了以外",F28<>"完了",F28=タスク一覧!$H$4))),AA28*1000000+COUNTIF($C$5:$C$300,"<"&C28)*1000+ROW(),1000000000000) -> 2041028
A29: T025 | B29: プロト | C29: ステージ | D29: ステージ1（仮レイアウト） | E29: S | F29: 一部実装 | G29: 10 | I29: StaticStageあり。プレイ可能区画・導線・配置が必要 | K29: 表示 | AA29: =IF(B29="プロト",1,IF(B29="アルファ",2,IF(B29="ベータ",3,IF(B29="マスター",4,5)))) -> 1 | AB29: =IF(AND(A29<>"",K29<>"非表示",IF(タスク一覧!$B$4="すべて",TRUE,B29=タスク一覧!$B$4),IF(タスク一覧!$E$4="すべて",TRUE,C29=タスク一覧!$E$4),IF(タスク一覧!$H$4="すべて",TRUE,IF(タスク一覧!$H$4="完了以外",F29<>"完了",F29=タスク一覧!$H$4))),AA29*1000000+COUNTIF($C$5:$C$300,"<"&C29)*1000+ROW(),1000000000000) -> 1013029
A30: T026 | B30: アルファ | C30: ステージ | D30: ステージ2 | E30: A | F30: 未着手 | G30: 10 | I30: 元表の項目 | K30: 表示 | AA30: =IF(B30="プロト",1,IF(B30="アルファ",2,IF(B30="ベータ",3,IF(B30="マスター",4,5)))) -> 2 | AB30: =IF(AND(A30<>"",K30<>"非表示",IF(タスク一覧!$B$4="すべて",TRUE,B30=タスク一覧!$B$4),IF(タスク一覧!$E$4="すべて",TRUE,C30=タスク一覧!$E$4),IF(タスク一覧!$H$4="すべて",TRUE,IF(タスク一覧!$H$4="完了以外",F30<>"完了",F30=タスク一覧!$H$4))),AA30*1000000+COUNTIF($C$5:$C$300,"<"&C30)*1000+ROW(),1000000000000) -> 2013030
A31: T027 | B31: アルファ | C31: ステージ | D31: ステージ3 | E31: A | F31: 未着手 | G31: 10 | I31: 元表の項目 | K31: 表示 | AA31: =IF(B31="プロト",1,IF(B31="アルファ",2,IF(B31="ベータ",3,IF(B31="マスター",4,5)))) -> 2 | AB31: =IF(AND(A31<>"",K31<>"非表示",IF(タスク一覧!$B$4="すべて",TRUE,B31=タスク一覧!$B$4),IF(タスク一覧!$E$4="すべて",TRUE,C31=タスク一覧!$E$4),IF(タスク一覧!$H$4="すべて",TRUE,IF(タスク一覧!$H$4="完了以外",F31<>"完了",F31=タスク一覧!$H$4))),AA31*1000000+COUNTIF($C$5:$C$300,"<"&C31)*1000+ROW(),1000000000000) -> 2013031
A32: T028 | B32: プロト | C32: システム | D32: アニメーション基盤・ブレンド | E32: S | F32: コードあり・要確認 | G32: 5 | H32: 15 | I32: Animator/AnimationLayerあり。遷移と見た目を確認 | K32: 表示 | AA32: =IF(B32="プロト",1,IF(B32="アルファ",2,IF(B32="ベータ",3,IF(B32="マスター",4,5)))) -> 1 | AB32: =IF(AND(A32<>"",K32<>"非表示",IF(タスク一覧!$B$4="すべて",TRUE,B32=タスク一覧!$B$4),IF(タスク一覧!$E$4="すべて",TRUE,C32=タスク一覧!$E$4),IF(タスク一覧!$H$4="すべて",TRUE,IF(タスク一覧!$H$4="完了以外",F32<>"完了",F32=タスク一覧!$H$4))),AA32*1000000+COUNTIF($C$5:$C$300,"<"&C32)*1000+ROW(),1000000000000) -> 1011032
A33: T029 | B33: プロト | C33: システム | D33: クラス設計・基盤整理 | E33: S | F33: 一部実装 | G33: 15 | H33: 10 | I33: GameObject/Component/StateMachine等の基盤あり。責務整理 | K33: 表示 | AA33: =IF(B33="プロト",1,IF(B33="アルファ",2,IF(B33="ベータ",3,IF(B33="マスター",4,5)))) -> 1 | AB33: =IF(AND(A33<>"",K33<>"非表示",IF(タスク一覧!$B$4="すべて",TRUE,B33=タスク一覧!$B$4),IF(タスク一覧!$E$4="すべて",TRUE,C33=タスク一覧!$E$4),IF(タスク一覧!$H$4="すべて",TRUE,IF(タスク一覧!$H$4="完了以外",F33<>"完了",F33=タスク一覧!$H$4))),AA33*1000000+COUNTIF($C$5:$C$300,"<"&C33)*1000+ROW(),1000000000000) -> 1011033
A34: T030 | B34: プロト | C34: 素材 | D34: モデル | E34: S | F34: 進行中 | G34: 5 | I34: Player/Gun/Walkerモデル参照あり。配置・スケール確認 | K34: 表示 | AA34: =IF(B34="プロト",1,IF(B34="アルファ",2,IF(B34="ベータ",3,IF(B34="マスター",4,5)))) -> 1 | AB34: =IF(AND(A34<>"",K34<>"非表示",IF(タスク一覧!$B$4="すべて",TRUE,B34=タスク一覧!$B$4),IF(タスク一覧!$E$4="すべて",TRUE,C34=タスク一覧!$E$4),IF(タスク一覧!$H$4="すべて",TRUE,IF(タスク一覧!$H$4="完了以外",F34<>"完了",F34=タスク一覧!$H$4))),AA34*1000000+COUNTIF($C$5:$C$300,"<"&C34)*1000+ROW(),1000000000000) -> 1037034
A35: T031 | B35: プロト | C35: 素材 | D35: アニメーション素材 | E35: S | F35: 進行中 | G35: 5 | I35: Animator基盤あり。必要なアニメーション組み込み | K35: 表示 | AA35: =IF(B35="プロト",1,IF(B35="アルファ",2,IF(B35="ベータ",3,IF(B35="マスター",4,5)))) -> 1 | AB35: =IF(AND(A35<>"",K35<>"非表示",IF(タスク一覧!$B$4="すべて",TRUE,B35=タスク一覧!$B$4),IF(タスク一覧!$E$4="すべて",TRUE,C35=タスク一覧!$E$4),IF(タスク一覧!$H$4="すべて",TRUE,IF(タスク一覧!$H$4="完了以外",F35<>"完了",F35=タスク一覧!$H$4))),AA35*1000000+COUNTIF($C$5:$C$300,"<"&C35)*1000+ROW(),1000000000000) -> 1037035
A36: T032 | B36: アルファ | C36: 素材 | D36: 画像・テクスチャ | E36: S | F36: 進行中 | G36: 5 | I36: Walker素材/テクスチャあり。ゲーム用調整と反映確認 | K36: 表示 | AA36: =IF(B36="プロト",1,IF(B36="アルファ",2,IF(B36="ベータ",3,IF(B36="マスター",4,5)))) -> 2 | AB36: =IF(AND(A36<>"",K36<>"非表示",IF(タスク一覧!$B$4="すべて",TRUE,B36=タスク一覧!$B$4),IF(タスク一覧!$E$4="すべて",TRUE,C36=タスク一覧!$E$4),IF(タスク一覧!$H$4="すべて",TRUE,IF(タスク一覧!$H$4="完了以外",F36<>"完了",F36=タスク一覧!$H$4))),AA36*1000000+COUNTIF($C$5:$C$300,"<"&C36)*1000+ROW(),1000000000000) -> 2037036
A37: T033 | B37: ベータ | C37: 素材 | D37: 音素材 | E37: S | F37: 未着手 | G37: 5 | I37: 元表の項目 | K37: 表示 | AA37: =IF(B37="プロト",1,IF(B37="アルファ",2,IF(B37="ベータ",3,IF(B37="マスター",4,5)))) -> 3 | AB37: =IF(AND(A37<>"",K37<>"非表示",IF(タスク一覧!$B$4="すべて",TRUE,B37=タスク一覧!$B$4),IF(タスク一覧!$E$4="すべて",TRUE,C37=タスク一覧!$E$4),IF(タスク一覧!$H$4="すべて",TRUE,IF(タスク一覧!$H$4="完了以外",F37<>"完了",F37=タスク一覧!$H$4))),AA37*1000000+COUNTIF($C$5:$C$300,"<"&C37)*1000+ROW(),1000000000000) -> 3037037
A38: T034 | B38: アルファ | C38: 演出 | D38: エフェクトマネージャー | E38: S | F38: 未着手 | G38: 2 | I38: 元表の項目 | K38: 表示 | AA38: =IF(B38="プロト",1,IF(B38="アルファ",2,IF(B38="ベータ",3,IF(B38="マスター",4,5)))) -> 2 | AB38: =IF(AND(A38<>"",K38<>"非表示",IF(タスク一覧!$B$4="すべて",TRUE,B38=タスク一覧!$B$4),IF(タスク一覧!$E$4="すべて",TRUE,C38=タスク一覧!$E$4),IF(タスク一覧!$H$4="すべて",TRUE,IF(タスク一覧!$H$4="完了以外",F38<>"完了",F38=タスク一覧!$H$4))),AA38*1000000+COUNTIF($C$5:$C$300,"<"&C38)*1000+ROW(),1000000000000) -> 2030038
A39: T035 | B39: アルファ | C39: 演出 | D39: エフェクト実装 | E39: S | F39: 未着手 | G39: 4 | I39: 命中・ハッキング・被弾など | K39: 表示 | AA39: =IF(B39="プロト",1,IF(B39="アルファ",2,IF(B39="ベータ",3,IF(B39="マスター",4,5)))) -> 2 | AB39: =IF(AND(A39<>"",K39<>"非表示",IF(タスク一覧!$B$4="すべて",TRUE,B39=タスク一覧!$B$4),IF(タスク一覧!$E$4="すべて",TRUE,C39=タスク一覧!$E$4),IF(タスク一覧!$H$4="すべて",TRUE,IF(タスク一覧!$H$4="完了以外",F39<>"完了",F39=タスク一覧!$H$4))),AA39*1000000+COUNTIF($C$5:$C$300,"<"&C39)*1000+ROW(),1000000000000) -> 2030039
A40: T036 | B40: アルファ | C40: 演出 | D40: サウンドマネージャー | E40: S | F40: 未着手 | G40: 2 | I40: 元表の項目 | K40: 表示 | AA40: =IF(B40="プロト",1,IF(B40="アルファ",2,IF(B40="ベータ",3,IF(B40="マスター",4,5)))) -> 2 | AB40: =IF(AND(A40<>"",K40<>"非表示",IF(タスク一覧!$B$4="すべて",TRUE,B40=タスク一覧!$B$4),IF(タスク一覧!$E$4="すべて",TRUE,C40=タスク一覧!$E$4),IF(タスク一覧!$H$4="すべて",TRUE,IF(タスク一覧!$H$4="完了以外",F40<>"完了",F40=タスク一覧!$H$4))),AA40*1000000+COUNTIF($C$5:$C$300,"<"&C40)*1000+ROW(),1000000000000) -> 2030040
...

Sheet マイルストーン
A1: マイルストーンとカレンダー
A2: 2026年9月〜12月のカレンダー、締切、段階ごとの目標をまとめています。必要作業時間/日は残りコストを残営業日で割った値です。
A3: 段階 | B3: 締切日 | C3: 残り日数 | D3: 残営業日 | E3: 累計予想コスト | F3: 累計実コスト | G3: 残りコスト | H3: 必要作業時間/日 | I3: 到達目標
A4: プロト | B4: 46326 | C4: =MAX(0,B4-TODAY()) -> 19 | D4: =MAX(0,NETWORKDAYS(TODAY()+1,B4)) -> 14 | E4: =SUMIF(タスク!$B$5:$B$300,"プロト",タスク!$G$5:$G$300) -> 177 | F4: =IF(COUNT(タスク!$H$5:$H$300)=0,"",SUMIF(タスク!$B$5:$B$300,"プロト",タスク!$H$5:$H$300)) -> 56 | G4: =E4-IF(F4="",0,F4) -> 121 | H4: =IF(D4=0,"",MAX(0,G4)/D4) -> 8.6428571 | I4: ゲームシーンだけでも遊べるように。プレイヤー、敵一体、ハッキング(黄色マス以外)、ステージ(仮)を実装する
A5: アルファ | B5: 46351 | C5: =MAX(0,B5-TODAY()) -> 44 | D5: =MAX(0,NETWORKDAYS(TODAY()+1,B5)) -> 32 | E5: =SUMIF(タスク!$B$5:$B$300,"プロト",タスク!$G$5:$G$300)+SUMIF(タスク!$B$5:$B$300,"アルファ",タスク!$G$5:$G$300) -> 284 | F5: =IF(COUNT(タスク!$H$5:$H$300)=0,"",SUMIF(タスク!$B$5:$B$300,"プロト",タスク!$H$5:$H$300)+SUMIF(タスク!$B$5:$B$300,"アルファ",タスク!$H$5:$H$300)) -> 56 | G5: =E5-IF(F5="",0,F5) -> 228 | H5: =IF(D5=0,"",MAX(0,G5)/D5) -> 7.125 | I5: 要素を増やしていく。ゲームシーン以外を実装(見た目は後)、ハッキングの黄色マス追加、敵追加、ステージ追加、改良
A6: ベータ | B6: 46372 | C6: =MAX(0,B6-TODAY()) -> 65 | D6: =MAX(0,NETWORKDAYS(TODAY()+1,B6)) -> 47 | E6: =SUMIF(タスク!$B$5:$B$300,"プロト",タスク!$G$5:$G$300)+SUMIF(タスク!$B$5:$B$300,"アルファ",タスク!$G$5:$G$300)+SUMIF(タスク!$B$5:$B$300,"ベータ",タスク!$G$5:$G$300) -> 309 | F6: =IF(COUNT(タスク!$H$5:$H$300)=0,"",SUMIF(タスク!$B$5:$B$300,"プロト",タスク!$H$5:$H$300)+SUMIF(タスク!$B$5:$B$300,"アルファ",タスク!$H$5:$H$300)+SUMIF(タスク!$B$5:$B$300,"ベータ",タスク!$H$5:$H$300)) -> 56 | G6: =E6-IF(F6="",0,F6) -> 253 | H6: =IF(D6=0,"",MAX(0,G6)/D6) -> 5.3829787 | I6: 見た目を良くしていく。同時にレベルデザインやその他の改良なども行う。
A7: マスター | B7: 46387 | C7: =MAX(0,B7-TODAY()) -> 80 | D7: =MAX(0,NETWORKDAYS(TODAY()+1,B7)) -> 58 | E7: =SUMIF(タスク!$B$5:$B$300,"プロト",タスク!$G$5:$G$300)+SUMIF(タスク!$B$5:$B$300,"アルファ",タスク!$G$5:$G$300)+SUMIF(タスク!$B$5:$B$300,"ベータ",タスク!$G$5:$G$300)+SUMIF(タスク!$B$5:$B$300,"マスター",タスク!$G$5:$G$300) -> 317 | F7: =IF(COUNT(タスク!$H$5:$H$300)=0,"",SUMIF(タスク!$B$5:$B$300,"プロト",タスク!$H$5:$H$300)+SUMIF(タスク!$B$5:$B$300,"アルファ",タスク!$H$5:$H$300)+SUMIF(タスク!$B$5:$B$300,"ベータ",タスク!$H$5:$H$300)+SUMIF(タスク!$B$5:$B$300,"マスター",タスク!$H$5:$H$300)) -> 56 | G7: =E7-IF(F7="",0,F7) -> 261 | H7: =IF(D7=0,"",MAX(0,G7)/D7) -> 4.5 | I7: 細かいところを調整。見た目とか難易度とか
A8: 締め切り | B8: 46387 | C8: =MAX(0,B8-TODAY()) -> 80 | D8: =MAX(0,NETWORKDAYS(TODAY()+1,B8)) -> 58 | E8: =SUMIF(タスク!$B$5:$B$300,"プロト",タスク!$G$5:$G$300)+SUMIF(タスク!$B$5:$B$300,"アルファ",タスク!$G$5:$G$300)+SUMIF(タスク!$B$5:$B$300,"ベータ",タスク!$G$5:$G$300)+SUMIF(タスク!$B$5:$B$300,"マスター",タスク!$G$5:$G$300) -> 317 | F8: =IF(COUNT(タスク!$H$5:$H$300)=0,"",SUMIF(タスク!$B$5:$B$300,"プロト",タスク!$H$5:$H$300)+SUMIF(タスク!$B$5:$B$300,"アルファ",タスク!$H$5:$H$300)+SUMIF(タスク!$B$5:$B$300,"ベータ",タスク!$H$5:$H$300)+SUMIF(タスク!$B$5:$B$300,"マスター",タスク!$H$5:$H$300)) -> 56 | G8: =E8-IF(F8="",0,F8) -> 261 | H8: =IF(D8=0,"",MAX(0,G8)/D8) -> 4.5 | I8: 締め切り
K12: 10月 2026年
K13: 日 | L13: 月 | M13: 火 | N13: 水 | O13: 木 | P13: 金 | Q13: 土
O14: 1 | P14: 2 | Q14: 3
K15: 4 | L15: 5 | M15: 6 | N15: 7 | O15: 8 | P15: 9 | Q15: 10
K16: 11 | L16: 12 | M16: 13 | N16: 14 | O16: 15 | P16: 16 | Q16: 17
K17: 18 | L17: 19 | M17: 20 | N17: 21 | O17: 22 | P17: 23 | Q17: 24
K18: 25 | L18: 26 | M18: 27 | N18: 28 | O18: 29 | P18: 30 | Q18: 31
K20: 11月 2026年
K21: 日 | L21: 月 | M21: 火 | N21: 水 | O21: 木 | P21: 金 | Q21: 土
K22: 1 | L22: 2 | M22: 3 | N22: 4 | O22: 5 | P22: 6 | Q22: 7
K23: 8 | L23: 9 | M23: 10 | N23: 11 | O23: 12 | P23: 13 | Q23: 14
K24: 15 | L24: 16 | M24: 17 | N24: 18 | O24: 19 | P24: 20 | Q24: 21
K25: 22 | L25: 23 | M25: 24 | N25: 25 | O25: 26 | P25: 27 | Q25: 28
K26: 29 | L26: 30
K28: 12月 2026年
K29: 日 | L29: 月 | M29: 火 | N29: 水 | O29: 木 | P29: 金 | Q29: 土
M30: 1 | N30: 2 | O30: 3 | P30: 4 | Q30: 5
K31: 6 | L31: 7 | M31: 8 | N31: 9 | O31: 10 | P31: 11 | Q31: 12
K32: 13 | L32: 14 | M32: 15 | N32: 16 | O32: 17 | P32: 18 | Q32: 19
K33: 20 | L33: 21 | M33: 22 | N33: 23 | O33: 24 | P33: 25 | Q33: 26
K34: 27 | L34: 28 | M34: 29 | N34: 30 | O34: 31

Sheet タスク一覧
A1: タスク一覧｜段階・カテゴリ順
A2: 追加・編集は「タスク」で行います。段階・カテゴリ・進捗で絞り込み、個別表示は「タスク」のK列で切り替えます。
A4: 段階 | B4: すべて | D4: カテゴリ | E4: すべて | G4: 進捗状況 | H4: すべて
A6: ID | B6: 段階 | C6: カテゴリ | D6: 作業項目 | E6: 優先度 | F6: 進捗状況 | G6: 予想コスト | H6: 実コスト | I6: コード確認メモ | J6: 補足
A7: =IFERROR(IF(SMALL(タスク!$AB$5:$AB$300,ROWS($A$7:A7))>=1000000000000,"",INDEX(タスク!A$5:A$300,MATCH(SMALL(タスク!$AB$5:$AB$300,ROWS($A$7:A7)),タスク!$AB$5:$AB$300,0))),"") -> T012 | B7: =IFERROR(IF(SMALL(タスク!$AB$5:$AB$300,ROWS($A$7:A7))>=1000000000000,"",INDEX(タスク!B$5:B$300,MATCH(SMALL(タスク!$AB$5:$AB$300,ROWS($A$7:A7)),タスク!$AB$5:$AB$300,0))),"") -> プロト | C7: =IFERROR(IF(SMALL(タスク!$AB$5:$AB$300,ROWS($A$7:A7))>=1000000000000,"",INDEX(タスク!C$5:C$300,MATCH(SMALL(タスク!$AB$5:$AB$300,ROWS($A$7:A7)),タスク!$AB$5:$AB$300,0))),"") -> カメラ | D7: =IFERROR(IF(SMALL(タスク!$AB$5:$AB$300,ROWS($A$7:A7))>=1000000000000,"",INDEX(タスク!D$5:D$300,MATCH(SMALL(タスク!$AB$5:$AB$300,ROWS($A$7:A7)),タスク!$AB$5:$AB$300,0))),"") -> 通常カメラ | E7: =IFERROR(IF(SMALL(タスク!$AB$5:$AB$300,ROWS($A$7:A7))>=1000000000000,"",INDEX(タスク!E$5:E$300,MATCH(SMALL(タスク!$AB$5:$AB$300,ROWS($A$7:A7)),タスク!$AB$5:$AB$300,0))),"") -> S | F7: =IFERROR(IF(SMALL(タスク!$AB$5:$AB$300,ROWS($A$7:A7))>=1000000000000,"",INDEX(タスク!F$5:F$300,MATCH(SMALL(タスク!$AB$5:$AB$300,ROWS($A$7:A7)),タスク!$AB$5:$AB$300,0))),"") -> 完了 | G7: =IFERROR(IF(SMALL(タスク!$AB$5:$AB$300,ROWS($A$7:A7))>=1000000000000,"",INDEX(タスク!G$5:G$300,MATCH(SMALL(タスク!$AB$5:$AB$300,ROWS($A$7:A7)),タスク!$AB$5:$AB$300,0))),"") -> 7 | H7: =IFERROR(IF(SMALL(タスク!$AB$5:$AB$300,ROWS($A$7:A7))>=1000000000000,"",INDEX(タスク!H$5:H$300,MATCH(SMALL(タスク!$AB$5:$AB$300,ROWS($A$7:A7)),タスク!$AB$5:$AB$300,0))),"") -> 5 | I7: =IFERROR(IF(SMALL(タスク!$AB$5:$AB$300,ROWS($A$7:A7))>=1000000000000,"",INDEX(タスク!I$5:I$300,MATCH(SMALL(タスク!$AB$5:$AB$300,ROWS($A$7:A7)),タスク!$AB$5:$AB$300,0))),"") -> Camera.cpp/hあり | J7: =IFERROR(IF(SMALL(タスク!$AB$5:$AB$300,ROWS($A$7:A7))>=1000000000000,"",INDEX(タスク!J$5:J$300,MATCH(SMALL(タスク!$AB$5:$AB$300,ROWS($A$7:A7)),タスク!$AB$5:$AB$300,0))),"") -> 0
A8: =IFERROR(IF(SMALL(タスク!$AB$5:$AB$300,ROWS($A$7:A8))>=1000000000000,"",INDEX(タスク!A$5:A$300,MATCH(SMALL(タスク!$AB$5:$AB$300,ROWS($A$7:A8)),タスク!$AB$5:$AB$300,0))),"") -> T013 | B8: =IFERROR(IF(SMALL(タスク!$AB$5:$AB$300,ROWS($A$7:A8))>=1000000000000,"",INDEX(タスク!B$5:B$300,MATCH(SMALL(タスク!$AB$5:$AB$300,ROWS($A$7:A8)),タスク!$AB$5:$AB$300,0))),"") -> プロト | C8: =IFERROR(IF(SMALL(タスク!$AB$5:$AB$300,ROWS($A$7:A8))>=1000000000000,"",INDEX(タスク!C$5:C$300,MATCH(SMALL(タスク!$AB$5:$AB$300,ROWS($A$7:A8)),タスク!$AB$5:$AB$300,0))),"") -> カメラ | D8: =IFERROR(IF(SMALL(タスク!$AB$5:$AB$300,ROWS($A$7:A8))>=1000000000000,"",INDEX(タスク!D$5:D$300,MATCH(SMALL(タスク!$AB$5:$AB$300,ROWS($A$7:A8)),タスク!$AB$5:$AB$300,0))),"") -> エイムカメラ | E8: =IFERROR(IF(SMALL(タスク!$AB$5:$AB$300,ROWS($A$7:A8))>=1000000000000,"",INDEX(タスク!E$5:E$300,MATCH(SMALL(タスク!$AB$5:$AB$300,ROWS($A$7:A8)),タスク!$AB$5:$AB$300,0))),"") -> S | F8: =IFERROR(IF(SMALL(タスク!$AB$5:$AB$300,ROWS($A$7:A8))>=1000000000000,"",INDEX(タスク!F$5:F$300,MATCH(SMALL(タスク!$AB$5:$AB$300,ROWS($A$7:A8)),タスク!$AB$5:$AB$300,0))),"") -> 一部実装 | G8: =IFERROR(IF(SMALL(タスク!$AB$5:$AB$300,ROWS($A$7:A8))>=1000000000000,"",INDEX(タスク!G$5:G$300,MATCH(SMALL(タスク!$AB$5:$AB$300,ROWS($A$7:A8)),タスク!$AB$5:$AB$300,0))),"") -> 7 | H8: =IFERROR(IF(SMALL(タスク!$AB$5:$AB$300,ROWS($A$7:A8))>=1000000000000,"",INDEX(タスク!H$5:H$300,MATCH(SMALL(タスク!$AB$5:$AB$300,ROWS($A$7:A8)),タスク!$AB$5:$AB$300,0))),"") -> 5 | I8: =IFERROR(IF(SMALL(タスク!$AB$5:$AB$300,ROWS($A$7:A8))>=1000000000000,"",INDEX(タスク!I$5:I$300,MATCH(SMALL(タスク!$AB$5:$AB$300,ROWS($A$7:A8)),タスク!$AB$5:$AB$300,0))),"") -> 照準時の視点処理をPlayerと統合確認 | J8: =IFERROR(IF(SMALL(タスク!$AB$5:$AB$300,ROWS($A$7:A8))>=1000000000000,"",INDEX(タスク!J$5:J$300,MATCH(SMALL(タスク!$AB$5:$AB$300,ROWS($A$7:A8)),タスク!$AB$5:$AB$300,0))),"") -> 0
A9: =IFERROR(IF(SMALL(タスク!$AB$5:$AB$300,ROWS($A$7:A9))>=1000000000000,"",INDEX(タスク!A$5:A$300,MATCH(SMALL(タスク!$AB$5:$AB$300,ROWS($A$7:A9)),タスク!$AB$5:$AB$300,0))),"") -> T038 | B9: =IFERROR(IF(SMALL(タスク!$AB$5:$AB$300,ROWS($A$7:A9))>=1000000000000,"",INDEX(タスク!B$5:B$300,MATCH(SMALL(タスク!$AB$5:$AB$300,ROWS($A$7:A9)),タスク!$AB$5:$AB$300,0))),"") -> プロト | C9: =IFERROR(IF(SMALL(タスク!$AB$5:$AB$300,ROWS($A$7:A9))>=1000000000000,"",INDEX(タスク!C$5:C$300,MATCH(SMALL(タスク!$AB$5:$AB$300,ROWS($A$7:A9)),タスク!$AB$5:$AB$300,0))),"") -> シーン | D9: =IFERROR(IF(SMALL(タスク!$AB$5:$AB$300,ROWS($A$7:A9))>=1000000000000,"",INDEX(タスク!D$5:D$300,MATCH(SMALL(タスク!$AB$5:$AB$300,ROWS($A$7:A9)),タスク!$AB$5:$AB$300,0))),"") -> シーンマネージャー | E9: =IFERROR(IF(SMALL(タスク!$AB$5:$AB$300,ROWS($A$7:A9))>=1000000000000,"",INDEX(タスク!E$5:E$300,MATCH(SMALL(タスク!$AB$5:$AB$300,ROWS($A$7:A9)),タスク!$AB$5:$AB$300,0))),"") -> S | F9: =IFERROR(IF(SMALL(タスク!$AB$5:$AB$300,ROWS($A$7:A9))>=1000000000000,"",INDEX(タスク!F$5:F$300,MATCH(SMALL(タスク!$AB$5:$AB$300,ROWS($A$7:A9)),タスク!$AB$5:$AB$300,0))),"") -> 完了 | G9: =IFERROR(IF(SMALL(タスク!$AB$5:$AB$300,ROWS($A$7:A9))>=1000000000000,"",INDEX(タスク!G$5:G$300,MATCH(SMALL(タスク!$AB$5:$AB$300,ROWS($A$7:A9)),タスク!$AB$5:$AB$300,0))),"") -> 3 | H9: =IFERROR(IF(SMALL(タスク!$AB$5:$AB$300,ROWS($A$7:A9))>=1000000000000,"",INDEX(タスク!H$5:H$300,MATCH(SMALL(タスク!$AB$5:$AB$300,ROWS($A$7:A9)),タスク!$AB$5:$AB$300,0))),"") -> 2 | I9: =IFERROR(IF(SMALL(タスク!$AB$5:$AB$300,ROWS($A$7:A9))>=1000000000000,"",INDEX(タスク!I$5:I$300,MATCH(SMALL(タスク!$AB$5:$AB$300,ROWS($A$7:A9)),タスク!$AB$5:$AB$300,0))),"") -> SceneManagerあり | J9: =IFERROR(IF(SMALL(タスク!$AB$5:$AB$300,ROWS($A$7:A9))>=1000000000000,"",INDEX(タスク!J$5:J$300,MATCH(SMALL(タスク!$AB$5:$AB$300,ROWS($A$7:A9)),タスク!$AB$5:$AB$300,0))),"") -> 0
A10: =IFERROR(IF(SMALL(タスク!$AB$5:$AB$300,ROWS($A$7:A10))>=1000000000000,"",INDEX(タスク!A$5:A$300,MATCH(SMALL(タスク!$AB$5:$AB$300,ROWS($A$7:A10)),タスク!$AB$5:$AB$300,0))),"") -> T039 | B10: =IFERROR(IF(SMALL(タスク!$AB$5:$AB$300,ROWS($A$7:A10))>=1000000000000,"",INDEX(タスク!B$5:B$300,MATCH(SMALL(タスク!$AB$5:$AB$300,ROWS($A$7:A10)),タスク!$AB$5:$AB$300,0))),"") -> プロト | C10: =IFERROR(IF(SMALL(タスク!$AB$5:$AB$300,ROWS($A$7:A10))>=1000000000000,"",INDEX(タスク!C$5:C$300,MATCH(SMALL(タスク!$AB$5:$AB$300,ROWS($A$7:A10)),タスク!$AB$5:$AB$300,0))),"") -> シーン | D10: =IFERROR(IF(SMALL(タスク!$AB$5:$AB$300,ROWS($A$7:A10))>=1000000000000,"",INDEX(タスク!D$5:D$300,MATCH(SMALL(タスク!$AB$5:$AB$300,ROWS($A$7:A10)),タスク!$AB$5:$AB$300,0))),"") -> ゲームシーン | E10: =IFERROR(IF(SMALL(タスク!$AB$5:$AB$300,ROWS($A$7:A10))>=1000000000000,"",INDEX(タスク!E$5:E$300,MATCH(SMALL(タスク!$AB$5:$AB$300,ROWS($A$7:A10)),タスク!$AB$5:$AB$300,0))),"") -> S | F10: =IFERROR(IF(SMALL(タスク!$AB$5:$AB$300,ROWS($A$7:A10))>=1000000000000,"",INDEX(タスク!F$5:F$300,MATCH(SMALL(タスク!$AB$5:$AB$300,ROWS($A$7:A10)),タスク!$AB$5:$AB$300,0))),"") -> 一部実装 | G10: =IFERROR(IF(SMALL(タスク!$AB$5:$AB$300,ROWS($A$7:A10))>=1000000000000,"",INDEX(タスク!G$5:G$300,MATCH(SMALL(タスク!$AB$5:$AB$300,ROWS($A$7:A10)),タスク!$AB$5:$AB$300,0))),"") -> 5 | H10: =IFERROR(IF(SMALL(タスク!$AB$5:$AB$300,ROWS($A$7:A10))>=1000000000000,"",INDEX(タスク!H$5:H$300,MATCH(SMALL(タスク!$AB$5:$AB$300,ROWS($A$7:A10)),タスク!$AB$5:$AB$300,0))),"") -> 0 | I10: =IFERROR(IF(SMALL(タスク!$AB$5:$AB$300,ROWS($A$7:A10))>=1000000000000,"",INDEX(タスク!I$5:I$300,MATCH(SMALL(タスク!$AB$5:$AB$300,ROWS($A$7:A10)),タスク!$AB$5:$AB$300,0))),"") -> SceneMainあり。ゲームループとプレイ条件を確認 | J10: =IFERROR(IF(SMALL(タスク!$AB$5:$AB$300,ROWS($A$7:A10))>=1000000000000,"",INDEX(タスク!J$5:J$300,MATCH(SMALL(タスク!$AB$5:$AB$300,ROWS($A$7:A10)),タスク!$AB$5:$AB$300,0))),"") -> 0
A11: =IFERROR(IF(SMALL(タスク!$AB$5:$AB$300,ROWS($A$7:A11))>=1000000000000,"",INDEX(タスク!A$5:A$300,MATCH(SMALL(タスク!$AB$5:$AB$300,ROWS($A$7:A11)),タスク!$AB$5:$AB$300,0))),"") -> T028 | B11: =IFERROR(IF(SMALL(タスク!$AB$5:$AB$300,ROWS($A$7:A11))>=1000000000000,"",INDEX(タスク!B$5:B$300,MATCH(SMALL(タスク!$AB$5:$AB$300,ROWS($A$7:A11)),タスク!$AB$5:$AB$300,0))),"") -> プロト | C11: =IFERROR(IF(SMALL(タスク!$AB$5:$AB$300,ROWS($A$7:A11))>=1000000000000,"",INDEX(タスク!C$5:C$300,MATCH(SMALL(タスク!$AB$5:$AB$300,ROWS($A$7:A11)),タスク!$AB$5:$AB$300,0))),"") -> システム | D11: =IFERROR(IF(SMALL(タスク!$AB$5:$AB$300,ROWS($A$7:A11))>=1000000000000,"",INDEX(タスク!D$5:D$300,MATCH(SMALL(タスク!$AB$5:$AB$300,ROWS($A$7:A11)),タスク!$AB$5:$AB$300,0))),"") -> アニメーション基盤・ブレンド | E11: =IFERROR(IF(SMALL(タスク!$AB$5:$AB$300,ROWS($A$7:A11))>=1000000000000,"",INDEX(タスク!E$5:E$300,MATCH(SMALL(タスク!$AB$5:$AB$300,ROWS($A$7:A11)),タスク!$AB$5:$AB$300,0))),"") -> S | F11: =IFERROR(IF(SMALL(タスク!$AB$5:$AB$300,ROWS($A$7:A11))>=1000000000000,"",INDEX(タスク!F$5:F$300,MATCH(SMALL(タスク!$AB$5:$AB$300,ROWS($A$7:A11)),タスク!$AB$5:$AB$300,0))),"") -> コードあり・要確認 | G11: =IFERROR(IF(SMALL(タスク!$AB$5:$AB$300,ROWS($A$7:A11))>=1000000000000,"",INDEX(タスク!G$5:G$300,MATCH(SMALL(タスク!$AB$5:$AB$300,ROWS($A$7:A11)),タスク!$AB$5:$AB$300,0))),"") -> 5 | H11: =IFERROR(IF(SMALL(タスク!$AB$5:$AB$300,ROWS($A$7:A11))>=1000000000000,"",INDEX(タスク!H$5:H$300,MATCH(SMALL(タスク!$AB$5:$AB$300,ROWS($A$7:A11)),タスク!$AB$5:$AB$300,0))),"") -> 15 | I11: =IFERROR(IF(SMALL(タスク!$AB$5:$AB$300,ROWS($A$7:A11))>=1000000000000,"",INDEX(タスク!I$5:I$300,MATCH(SMALL(タスク!$AB$5:$AB$300,ROWS($A$7:A11)),タスク!$AB$5:$AB$300,0))),"") -> Animator/AnimationLayerあり。遷移と見た目を確認 | J11: =IFERROR(IF(SMALL(タスク!$AB$5:$AB$300,ROWS($A$7:A11))>=1000000000000,"",INDEX(タスク!J$5:J$300,MATCH(SMALL(タスク!$AB$5:$AB$300,ROWS($A$7:A11)),タスク!$AB$5:$AB$300,0))),"") -> 0
A12: =IFERROR(IF(SMALL(タスク!$AB$5:$AB$300,ROWS($A$7:A12))>=1000000000000,"",INDEX(タスク!A$5:A$300,MATCH(SMALL(タスク!$AB$5:$AB$300,ROWS($A$7:A12)),タスク!$AB$5:$AB$300,0))),"") -> T029 | B12: =IFERROR(IF(SMALL(タスク!$AB$5:$AB$300,ROWS($A$7:A12))>=1000000000000,"",INDEX(タスク!B$5:B$300,MATCH(SMALL(タスク!$AB$5:$AB$300,ROWS($A$7:A12)),タスク!$AB$5:$AB$300,0))),"") -> プロト | C12: =IFERROR(IF(SMALL(タスク!$AB$5:$AB$300,ROWS($A$7:A12))>=1000000000000,"",INDEX(タスク!C$5:C$300,MATCH(SMALL(タスク!$AB$5:$AB$300,ROWS($A$7:A12)),タスク!$AB$5:$AB$300,0))),"") -> システム | D12: =IFERROR(IF(SMALL(タスク!$AB$5:$AB$300,ROWS($A$7:A12))>=1000000000000,"",INDEX(タスク!D$5:D$300,MATCH(SMALL(タスク!$AB$5:$AB$300,ROWS($A$7:A12)),タスク!$AB$5:$AB$300,0))),"") -> クラス設計・基盤整理 | E12: =IFERROR(IF(SMALL(タスク!$AB$5:$AB$300,ROWS($A$7:A12))>=1000000000000,"",INDEX(タスク!E$5:E$300,MATCH(SMALL(タスク!$AB$5:$AB$300,ROWS($A$7:A12)),タスク!$AB$5:$AB$300,0))),"") -> S | F12: =IFERROR(IF(SMALL(タスク!$AB$5:$AB$300,ROWS($A$7:A12))>=1000000000000,"",INDEX(タスク!F$5:F$300,MATCH(SMALL(タスク!$AB$5:$AB$300,ROWS($A$7:A12)),タスク!$AB$5:$AB$300,0))),"") -> 一部実装 | G12: =IFERROR(IF(SMALL(タスク!$AB$5:$AB$300,ROWS($A$7:A12))>=1000000000000,"",INDEX(タスク!G$5:G$300,MATCH(SMALL(タスク!$AB$5:$AB$300,ROWS($A$7:A12)),タスク!$AB$5:$AB$300,0))),"") -> 15 | H12: =IFERROR(IF(SMALL(タスク!$AB$5:$AB$300,ROWS($A$7:A12))>=1000000000000,"",INDEX(タスク!H$5:H$300,MATCH(SMALL(タスク!$AB$5:$AB$300,ROWS($A$7:A12)),タスク!$AB$5:$AB$300,0))),"") -> 10 | I12: =IFERROR(IF(SMALL(タスク!$AB$5:$AB$300,ROWS($A$7:A12))>=1000000000000,"",INDEX(タスク!I$5:I$300,MATCH(SMALL(タスク!$AB$5:$AB$300,ROWS($A$7:A12)),タスク!$AB$5:$AB$300,0))),"") -> GameObject/Component/StateMachine等の基盤あり。責務整理 | J12: =IFERROR(IF(SMALL(タスク!$AB$5:$AB$300,ROWS($A$7:A12))>=1000000000000,"",INDEX(タスク!J$5:J$300,MATCH(SMALL(タスク!$AB$5:$AB$300,ROWS($A$7:A12)),タスク!$AB$5:$AB$300,0))),"") -> 0
A13: =IFERROR(IF(SMALL(タスク!$AB$5:$AB$300,ROWS($A$7:A13))>=1000000000000,"",INDEX(タスク!A$5:A$300,MATCH(SMALL(タスク!$AB$5:$AB$300,ROWS($A$7:A13)),タスク!$AB$5:$AB$300,0))),"") -> T025 | B13: =IFERROR(IF(SMALL(タスク!$AB$5:$AB$300,ROWS($A$7:A13))>=1000000000000,"",INDEX(タスク!B$5:B$300,MATCH(SMALL(タスク!$AB$5:$AB$300,ROWS($A$7:A13)),タスク!$AB$5:$AB$300,0))),"") -> プロト | C13: =IFERROR(IF(SMALL(タスク!$AB$5:$AB$300,ROWS($A$7:A13))>=1000000000000,"",INDEX(タスク!C$5:C$300,MATCH(SMALL(タスク!$AB$5:$AB$300,ROWS($A$7:A13)),タスク!$AB$5:$AB$300,0))),"") -> ステージ | D13: =IFERROR(IF(SMALL(タスク!$AB$5:$AB$300,ROWS($A$7:A13))>=1000000000000,"",INDEX(タスク!D$5:D$300,MATCH(SMALL(タスク!$AB$5:$AB$300,ROWS($A$7:A13)),タスク!$AB$5:$AB$300,0))),"") -> ステージ1（仮レイアウト） | E13: =IFERROR(IF(SMALL(タスク!$AB$5:$AB$300,ROWS($A$7:A13))>=1000000000000,"",INDEX(タスク!E$5:E$300,MATCH(SMALL(タスク!$AB$5:$AB$300,ROWS($A$7:A13)),タスク!$AB$5:$AB$300,0))),"") -> S | F13: =IFERROR(IF(SMALL(タスク!$AB$5:$AB$300,ROWS($A$7:A13))>=1000000000000,"",INDEX(タスク!F$5:F$300,MATCH(SMALL(タスク!$AB$5:$AB$300,ROWS($A$7:A13)),タスク!$AB$5:$AB$300,0))),"") -> 一部実装 | G13: =IFERROR(IF(SMALL(タスク!$AB$5:$AB$300,ROWS($A$7:A13))>=1000000000000,"",INDEX(タスク!G$5:G$300,MATCH(SMALL(タスク!$AB$5:$AB$300,ROWS($A$7:A13)),タスク!$AB$5:$AB$300,0))),"") -> 10 | H13: =IFERROR(IF(SMALL(タスク!$AB$5:$AB$300,ROWS($A$7:A13))>=1000000000000,"",INDEX(タスク!H$5:H$300,MATCH(SMALL(タスク!$AB$5:$AB$300,ROWS($A$7:A13)),タスク!$AB$5:$AB$300,0))),"") -> 0 | I13: =IFERROR(IF(SMALL(タスク!$AB$5:$AB$300,ROWS($A$7:A13))>=1000000000000,"",INDEX(タスク!I$5:I$300,MATCH(SMALL(タスク!$AB$5:$AB$300,ROWS($A$7:A13)),タスク!$AB$5:$AB$300,0))),"") -> StaticStageあり。プレイ可能区画・導線・配置が必要 | J13: =IFERROR(IF(SMALL(タスク!$AB$5:$AB$300,ROWS($A$7:A13))>=1000000000000,"",INDEX(タスク!J$5:J$300,MATCH(SMALL(タスク!$AB$5:$AB$300,ROWS($A$7:A13)),タスク!$AB$5:$AB$300,0))),"") -> 0
A14: =IFERROR(IF(SMALL(タスク!$AB$5:$AB$300,ROWS($A$7:A14))>=1000000000000,"",INDEX(タスク!A$5:A$300,MATCH(SMALL(タスク!$AB$5:$AB$300,ROWS($A$7:A14)),タスク!$AB$5:$AB$300,0))),"") -> T052 | B14: =IFERROR(IF(SMALL(タスク!$AB$5:$AB$300,ROWS($A$7:A14))>=1000000000000,"",INDEX(タスク!B$5:B$300,MATCH(SMALL(タスク!$AB$5:$AB$300,ROWS($A$7:A14)),タスク!$AB$5:$AB$300,0))),"") -> プロト | C14: =IFERROR(IF(SMALL(タスク!$AB$5:$AB$300,ROWS($A$7:A14))>=1000000000000,"",INDEX(タスク!C$5:C$300,MATCH(SMALL(タスク!$AB$5:$AB$300,ROWS($A$7:A14)),タスク!$AB$5:$AB$300,0))),"") -> ステージ | D14: =IFERROR(IF(SMALL(タスク!$AB$5:$AB$300,ROWS($A$7:A14))>=1000000000000,"",INDEX(タスク!D$5:D$300,MATCH(SMALL(タスク!$AB$5:$AB$300,ROWS($A$7:A14)),タスク!$AB$5:$AB$300,0))),"") -> ステージ1の衝突ブロックアウト・進行確認 | E14: =IFERROR(IF(SMALL(タスク!$AB$5:$AB$300,ROWS($A$7:A14))>=1000000000000,"",INDEX(タスク!E$5:E$300,MATCH(SMALL(タスク!$AB$5:$AB$300,ROWS($A$7:A14)),タスク!$AB$5:$AB$300,0))),"") -> S | F14: =IFERROR(IF(SMALL(タスク!$AB$5:$AB$300,ROWS($A$7:A14))>=1000000000000,"",INDEX(タスク!F$5:F$300,MATCH(SMALL(タスク!$AB$5:$AB$300,ROWS($A$7:A14)),タスク!$AB$5:$AB$300,0))),"") -> 計画追加 | G14: =IFERROR(IF(SMALL(タスク!$AB$5:$AB$300,ROWS($A$7:A14))>=1000000000000,"",INDEX(タスク!G$5:G$300,MATCH(SMALL(タスク!$AB$5:$AB$300,ROWS($A$7:A14)),タスク!$AB$5:$AB$300,0))),"") -> 8 | H14: =IFERROR(IF(SMALL(タスク!$AB$5:$AB$300,ROWS($A$7:A14))>=1000000000000,"",INDEX(タスク!H$5:H$300,MATCH(SMALL(タスク!$AB$5:$AB$300,ROWS($A$7:A14)),タスク!$AB$5:$AB$300,0))),"") -> 0 | I14: =IFERROR(IF(SMALL(タスク!$AB$5:$AB$300,ROWS($A$7:A14))>=1000000000000,"",INDEX(タスク!I$5:I$300,MATCH(SMALL(タスク!$AB$5:$AB$300,ROWS($A$7:A14)),タスク!$AB$5:$AB$300,0))),"") -> StaticStageに移動・射撃・ハッキング可能な導線を追加 | J14: =IFERROR(IF(SMALL(タスク!$AB$5:$AB$300,ROWS($A$7:A14))>=1000000000000,"",INDEX(タスク!J$5:J$300,MATCH(SMALL(タスク!$AB$5:$AB$300,ROWS($A$7:A14)),タスク!$AB$5:$AB$300,0))),"") -> 0
A15: =IFERROR(IF(SMALL(タスク!$AB$5:$AB$300,ROWS($A$7:A15))>=1000000000000,"",INDEX(タスク!A$5:A$300,MATCH(SMALL(タスク!$AB$5:$AB$300,ROWS($A$7:A15)),タスク!$AB$5:$AB$300,0))),"") -> T014 | B15: =IFERROR(IF(SMALL(タスク!$AB$5:$AB$300,ROWS($A$7:A15))>=1000000000000,"",INDEX(タスク!B$5:B$300,MATCH(SMALL(タスク!$AB$5:$AB$300,ROWS($A$7:A15)),タスク!$AB$5:$AB$300,0))),"") -> プロト | C15: =IFERROR(IF(SMALL(タスク!$AB$5:$AB$300,ROWS($A$7:A15))>=1000000000000,"",INDEX(タスク!C$5:C$300,MATCH(SMALL(タスク!$AB$5:$AB$300,ROWS($A$7:A15)),タスク!$AB$5:$AB$300,0))),"") -> ハッキング | D15: =IFERROR(IF(SMALL(タスク!$AB$5:$AB$300,ROWS($A$7:A15))>=1000000000000,"",INDEX(タスク!D$5:D$300,MATCH(SMALL(タスク!$AB$5:$AB$300,ROWS($A$7:A15)),タスク!$AB$5:$AB$300,0))),"") -> 盤面生成とデータ調整 | E15: =IFERROR(IF(SMALL(タスク!$AB$5:$AB$300,ROWS($A$7:A15))>=1000000000000,"",INDEX(タスク!E$5:E$300,MATCH(SMALL(タスク!$AB$5:$AB$300,ROWS($A$7:A15)),タスク!$AB$5:$AB$300,0))),"") -> S | F15: =IFERROR(IF(SMALL(タスク!$AB$5:$AB$300,ROWS($A$7:A15))>=1000000000000,"",INDEX(タスク!F$5:F$300,MATCH(SMALL(タスク!$AB$5:$AB$300,ROWS($A$7:A15)),タスク!$AB$5:$AB$300,0))),"") -> 一部実装 | G15: =IFERROR(IF(SMALL(タスク!$AB$5:$AB$300,ROWS($A$7:A15))>=1000000000000,"",INDEX(タスク!G$5:G$300,MATCH(SMALL(タスク!$AB$5:$AB$300,ROWS($A$7:A15)),タスク!$AB$5:$AB$300,0))),"") -> 7 | H15: =IFERROR(IF(SMALL(タスク!$AB$5:$AB$300,ROWS($A$7:A15))>=1000000000000,"",INDEX(タスク!H$5:H$300,MATCH(SMALL(タスク!$AB$5:$AB$300,ROWS($A$7:A15)),タスク!$AB$5:$AB$300,0))),"") -> 0 | I15: =IFERROR(IF(SMALL(タスク!$AB$5:$AB$300,ROWS($A$7:A15))>=1000000000000,"",INDEX(タスク!I$5:I$300,MATCH(SMALL(タスク!$AB$5:$AB$300,ROWS($A$7:A15)),タスク!$AB$5:$AB$300,0))),"") -> HackingManager/Hackableあり。盤面の外部データ化・調整性が残る | J15: =IFERROR(IF(SMALL(タスク!$AB$5:$AB$300,ROWS($A$7:A15))>=1000000000000,"",INDEX(タスク!J$5:J$300,MATCH(SMALL(タスク!$AB$5:$AB$300,ROWS($A$7:A15)),タスク!$AB$5:$AB$300,0))),"") -> 0
A16: =IFERROR(IF(SMALL(タスク!$AB$5:$AB$300,ROWS($A$7:A16))>=1000000000000,"",INDEX(タスク!A$5:A$300,MATCH(SMALL(タスク!$AB$5:$AB$300,ROWS($A$7:A16)),タスク!$AB$5:$AB$300,0))),"") -> T015 | B16: =IFERROR(IF(SMALL(タスク!$AB$5:$AB$300,ROWS($A$7:A16))>=1000000000000,"",INDEX(タスク!B$5:B$300,MATCH(SMALL(タスク!$AB$5:$AB$300,ROWS($A$7:A16)),タスク!$AB$5:$AB$300,0))),"") -> プロト | C16: =IFERROR(IF(SMALL(タスク!$AB$5:$AB$300,ROWS($A$7:A16))>=1000000000000,"",INDEX(タスク!C$5:C$300,MATCH(SMALL(タスク!$AB$5:$AB$300,ROWS($A$7:A16)),タスク!$AB$5:$AB$300,0))),"") -> ハッキング | D16: =IFERROR(IF(SMALL(タスク!$AB$5:$AB$300,ROWS($A$7:A16))>=1000000000000,"",INDEX(タスク!D$5:D$300,MATCH(SMALL(タスク!$AB$5:$AB$300,ROWS($A$7:A16)),タスク!$AB$5:$AB$300,0))),"") -> 盤面移動と経路制約 | E16: =IFERROR(IF(SMALL(タスク!$AB$5:$AB$300,ROWS($A$7:A16))>=1000000000000,"",INDEX(タスク!E$5:E$300,MATCH(SMALL(タスク!$AB$5:$AB$300,ROWS($A$7:A16)),タスク!$AB$5:$AB$300,0))),"") -> S | F16: =IFERROR(IF(SMALL(タスク!$AB$5:$AB$300,ROWS($A$7:A16))>=1000000000000,"",INDEX(タスク!F$5:F$300,MATCH(SMALL(タスク!$AB$5:$AB$300,ROWS($A$7:A16)),タスク!$AB$5:$AB$300,0))),"") -> コードあり・要確認 | G16: =IFERROR(IF(SMALL(タスク!$AB$5:$AB$300,ROWS($A$7:A16))>=1000000000000,"",INDEX(タスク!G$5:G$300,MATCH(SMALL(タスク!$AB$5:$AB$300,ROWS($A$7:A16)),タスク!$AB$5:$AB$300,0))),"") -> 5 | H16: =IFERROR(IF(SMALL(タスク!$AB$5:$AB$300,ROWS($A$7:A16))>=1000000000000,"",INDEX(タスク!H$5:H$300,MATCH(SMALL(タスク!$AB$5:$AB$300,ROWS($A$7:A16)),タスク!$AB$5:$AB$300,0))),"") -> 0 | I16: =IFERROR(IF(SMALL(タスク!$AB$5:$AB$300,ROWS($A$7:A16))>=1000000000000,"",INDEX(タスク!I$5:I$300,MATCH(SMALL(タスク!$AB$5:$AB$300,ROWS($A$7:A16)),タスク!$AB$5:$AB$300,0))),"") -> Hackableの移動処理あり。全マス条件を検証 | J16: =IFERROR(IF(SMALL(タスク!$AB$5:$AB$300,ROWS($A$7:A16))>=1000000000000,"",INDEX(タスク!J$5:J$300,MATCH(SMALL(タスク!$AB$5:$AB$300,ROWS($A$7:A16)),タスク!$AB$5:$AB$300,0))),"") -> 0
A17: =IFERROR(IF(SMALL(タスク!$AB$5:$AB$300,ROWS($A$7:A17))>=1000000000000,"",INDEX(タスク!A$5:A$300,MATCH(SMALL(タスク!$AB$5:$AB$300,ROWS($A$7:A17)),タスク!$AB$5:$AB$300,0))),"") -> T016 | B17: =IFERROR(IF(SMALL(タスク!$AB$5:$AB$300,ROWS($A$7:A17))>=1000000000000,"",INDEX(タスク!B$5:B$300,MATCH(SMALL(タスク!$AB$5:$AB$300,ROWS($A$7:A17)),タスク!$AB$5:$AB$300,0))),"") -> プロト | C17: =IFERROR(IF(SMALL(タスク!$AB$5:$AB$300,ROWS($A$7:A17))>=1000000000000,"",INDEX(タスク!C$5:C$300,MATCH(SMALL(タスク!$AB$5:$AB$300,ROWS($A$7:A17)),タスク!$AB$5:$AB$300,0))),"") -> ハッキング | D17: =IFERROR(IF(SMALL(タスク!$AB$5:$AB$300,ROWS($A$7:A17))>=1000000000000,"",INDEX(タスク!D$5:D$300,MATCH(SMALL(タスク!$AB$5:$AB$300,ROWS($A$7:A17)),タスク!$AB$5:$AB$300,0))),"") -> 成功・失敗の発動 | E17: =IFERROR(IF(SMALL(タスク!$AB$5:$AB$300,ROWS($A$7:A17))>=1000000000000,"",INDEX(タスク!E$5:E$300,MATCH(SMALL(タスク!$AB$5:$AB$300,ROWS($A$7:A17)),タスク!$AB$5:$AB$300,0))),"") -> S | F17: =IFERROR(IF(SMALL(タスク!$AB$5:$AB$300,ROWS($A$7:A17))>=1000000000000,"",INDEX(タスク!F$5:F$300,MATCH(SMALL(タスク!$AB$5:$AB$300,ROWS($A$7:A17)),タスク!$AB$5:$AB$300,0))),"") -> 一部実装 | G17: =IFERROR(IF(SMALL(タスク!$AB$5:$AB$300,ROWS($A$7:A17))>=1000000000000,"",INDEX(タスク!G$5:G$300,MATCH(SMALL(タスク!$AB$5:$AB$300,ROWS($A$7:A17)),タスク!$AB$5:$AB$300,0))),"") -> 7 | H17: =IFERROR(IF(SMALL(タスク!$AB$5:$AB$300,ROWS($A$7:A17))>=1000000000000,"",INDEX(タスク!H$5:H$300,MATCH(SMALL(タスク!$AB$5:$AB$300,ROWS($A$7:A17)),タスク!$AB$5:$AB$300,0))),"") -> 0 | I17: =IFERROR(IF(SMALL(タスク!$AB$5:$AB$300,ROWS($A$7:A17))>=1000000000000,"",INDEX(タスク!I$5:I$300,MATCH(SMALL(タスク!$AB$5:$AB$300,ROWS($A$7:A17)),タスク!$AB$5:$AB$300,0))),"") -> HackingManager/Hackableあり。敵状態・リセット連携を要確認 | J17: =IFERROR(IF(SMALL(タスク!$AB$5:$AB$300,ROWS($A$7:A17))>=1000000000000,"",INDEX(タスク!J$5:J$300,MATCH(SMALL(タスク!$AB$5:$AB$300,ROWS($A$7:A17)),タスク!$AB$5:$AB$300,0))),"") -> 0
A18: =IFERROR(IF(SMALL(タスク!$AB$5:$AB$300,ROWS($A$7:A18))>=1000000000000,"",INDEX(タスク!A$5:A$300,MATCH(SMALL(タスク!$AB$5:$AB$300,ROWS($A$7:A18)),タスク!$AB$5:$AB$300,0))),"") -> T017 | B18: =IFERROR(IF(SMALL(タスク!$AB$5:$AB$300,ROWS($A$7:A18))>=1000000000000,"",INDEX(タスク!B$5:B$300,MATCH(SMALL(タスク!$AB$5:$AB$300,ROWS($A$7:A18)),タスク!$AB$5:$AB$300,0))),"") -> プロト | C18: =IFERROR(IF(SMALL(タスク!$AB$5:$AB$300,ROWS($A$7:A18))>=1000000000000,"",INDEX(タスク!C$5:C$300,MATCH(SMALL(タスク!$AB$5:$AB$300,ROWS($A$7:A18)),タスク!$AB$5:$AB$300,0))),"") -> ハッキング | D18: =IFERROR(IF(SMALL(タスク!$AB$5:$AB$300,ROWS($A$7:A18))>=1000000000000,"",INDEX(タスク!D$5:D$300,MATCH(SMALL(タスク!$AB$5:$AB$300,ROWS($A$7:A18)),タスク!$AB$5:$AB$300,0))),"") -> ハッキング特殊効果 | E18: =IFERROR(IF(SMALL(タスク!$AB$5:$AB$300,ROWS($A$7:A18))>=1000000000000,"",INDEX(タスク!E$5:E$300,MATCH(SMALL(タスク!$AB$5:$AB$300,ROWS($A$7:A18)),タスク!$AB$5:$AB$300,0))),"") -> S | F18: =IFERROR(IF(SMALL(タスク!$AB$5:$AB$300,ROWS($A$7:A18))>=1000000000000,"",INDEX(タスク!F$5:F$300,MATCH(SMALL(タスク!$AB$5:$AB$300,ROWS($A$7:A18)),タスク!$AB$5:$AB$300,0))),"") -> 一部実装 | G18: =IFERROR(IF(SMALL(タスク!$AB$5:$AB$300,ROWS($A$7:A18))>=1000000000000,"",INDEX(タスク!G$5:G$300,MATCH(SMALL(タスク!$AB$5:$AB$300,ROWS($A$7:A18)),タスク!$AB$5:$AB$300,0))),"") -> 8 | H18: =IFERROR(IF(SMALL(タスク!$AB$5:$AB$300,ROWS($A$7:A18))>=1000000000000,"",INDEX(タスク!H$5:H$300,MATCH(SMALL(タスク!$AB$5:$AB$300,ROWS($A$7:A18)),タスク!$AB$5:$AB$300,0))),"") -> 0 | I18: =IFERROR(IF(SMALL(タスク!$AB$5:$AB$300,ROWS($A$7:A18))>=1000000000000,"",INDEX(タスク!I$5:I$300,MATCH(SMALL(タスク!$AB$5:$AB$300,ROWS($A$7:A18)),タスク!$AB$5:$AB$300,0))),"") -> 黄色マス等。銃強化・伝播・停止などを追加 | J18: =IFERROR(IF(SMALL(タスク!$AB$5:$AB$300,ROWS($A$7:A18))>=1000000000000,"",INDEX(タスク!J$5:J$300,MATCH(SMALL(タスク!$AB$5:$AB$300,ROWS($A$7:A18)),タスク!$AB$5:$AB$300,0))),"") -> 0
... A306: =IFERROR(IF(SMALL(タスク!$AB$5:$AB$300,ROWS($A$7:A306))>=1000000000000,"",INDEX(タスク!A$5:A$300,MATCH(SMALL(タスク!$AB$5:$AB$300,ROWS($A$7:A306)),タスク!$AB$5:$AB$300,0))),"") | B306: =IFERROR(IF(SMALL(タスク!$AB$5:$AB$300,ROWS($A$7:A306))>=1000000000000,"",INDEX(タスク!B$5:B$300,MATCH(SMALL(タスク!$AB$5:$AB$300,ROWS($A$7:A306)),タスク!$AB$5:$AB$300,0))),"") | C306: =IFERROR(IF(SMALL(タスク!$AB$5:$AB$300,ROWS($A$7:A306))>=1000000000000,"",INDEX(タスク!C$5:C$300,MATCH(SMALL(タスク!$AB$5:$AB$300,ROWS($A$7:A306)),タスク!$AB$5:$AB$300,0))),"") | D306: =IFERROR(IF(SMALL(タスク!$AB$5:$AB$300,ROWS($A$7:A306))>=1000000000000,"",INDEX(タスク!D$5:D$300,MATCH(SMALL(タスク!$AB$5:$AB$300,ROWS($A$7:A306)),タスク!$AB$5:$AB$300,0))),"") | E306: =IFERROR(IF(SMALL(タスク!$AB$5:$AB$300,ROWS($A$7:A306))>=1000000000000,"",INDEX(タスク!E$5:E$300,MATCH(SMALL(タスク!$AB$5:$AB$300,ROWS($A$7:A306)),タスク!$AB$5:$AB$300,0))),"") | F306: =IFERROR(IF(SMALL(タスク!$AB$5:$AB$300,ROWS($A$7:A306))>=1000000000000,"",INDEX(タスク!F$5:F$300,MATCH(SMALL(タスク!$AB$5:$AB$300,ROWS($A$7:A306)),タスク!$AB$5:$AB$300,0))),"") | G306: =IFERROR(IF(SMALL(タスク!$AB$5:$AB$300,ROWS($A$7:A306))>=1000000000000,"",INDEX(タスク!G$5:G$300,MATCH(SMALL(タスク!$AB$5:$AB$300,ROWS($A$7:A306)),タスク!$AB$5:$AB$300,0))),"") | H306: =IFERROR(IF(SMALL(タスク!$AB$5:$AB$300,ROWS($A$7:A306))>=1000000000000,"",INDEX(タスク!H$5:H$300,MATCH(SMALL(タスク!$AB$5:$AB$300,ROWS($A$7:A306)),タスク!$AB$5:$AB$300,0))),"") | I306: =IFERROR(IF(SMALL(タスク!$AB$5:$AB$300,ROWS($A$7:A306))>=1000000000000,"",INDEX(タスク!I$5:I$300,MATCH(SMALL(タスク!$AB$5:$AB$300,ROWS($A$7:A306)),タスク!$AB$5:$AB$300,0))),"") | J306: =IFERROR(IF(SMALL(タスク!$AB$5:$AB$300,ROWS($A$7:A306))>=1000000000000,"",INDEX(タスク!J$5:J$300,MATCH(SMALL(タスク!$AB$5:$AB$300,ROWS($A$7:A306)),タスク!$AB$5:$AB$300,0))),"")
